Workbook

Sheet Summary1
A1: DANH SÁCH CHỨNG NHẬN VẬN HÀNH | CN1: Số (Form Code): ADL/F/EHS/022-04
CN2: Lần hiệu chỉnh (Revision No.): 00
CN3: Lần ban hành (Issuance No.): 01
CN4: Ngày hiệu lực (Effective date): 01/04/2025
A6: STT | B6: MSNV | C6: TÊN | D6: BỘ PHẬN | E6: NGÀY ĐÁNH GIÁ | F6: HẠNG MỤC ĐƯỢC ĐÀO TẠO
F7: Materials + Paint Blending | P7: G_Cutting | W7: G_Rolling | AH7: G_Finishing | AO7: G_Dipping | AX7: G_Graphics | BE7: A_Blank | BR7: A_Graphics | BU7: Kayak | CH7: A_QC | CM7: G_QC Blank | CR7: G_QC Cosmetics | CW7: MTN | DA7: Note
F8: Xe nâng/Nâng tay | G8: Sử dụng vật sắc nhọn | H8: Xe nâng phuy | I8: Máy tái chế Acetone | J8: Máy lắc sơn/ đo độ nhớt | K8: Máy lọc sơn | L8: Lò Oven Nhỏ | M8: Vận chuyển, lưu trữ HC | N8: Mở cửa kho đông | O8: Thang nâng | P8: Sheet | Q8: Xe nâng prepreg | R8: Shear | S8: Die Cut | T8: Splicing | U8: Máy ép Hashima | V8: Máy hút chân không | W8: Bàn nhiệt | X8: Máy CDI | Y8: Máy Revo | Z8: Máy Auto rolling | AA8: Máy Cello Đứng | AB8: Máy Cello Ngang | AC8: Lò Oven | AD8: Máy Rút Dây Cello | AE8: Máy Rút Mandrell | AF8: Máy Rửa Mandrell | AG8: Máy Đo/Uốn Thẳng Mandrell | AH8: Máy Dual Saw | AI8: Wash | AJ8: Máy Mài - Đánh Bóng Máy Buff | AK8: Máy Paragon | AL8: Máy Khắc Laser | AM8: Máy Auto Sanding | AN8: Máy Cắt Dấu Flex | AO8: Máy Bắn Cát | AP8: Máy Scrap Shaft | AQ8: Máy Lắc Sơn | AR8: Máy / Kệ Khuấy Sơn | AS8: Máy rửa mắt/ Vòi tắm rửa khẩn cấp | AT8: Máy Phun Sơn Tự Động | AU8: Máy Tip-Blast | AV8: Máy Đánh Bóng | AW8: Máy Auto Dipping | AX8: Máy Decal | AY8: Máy In Lụa - Băng Tải Nhiệt | AZ8: Máy Chụp Khung Lụa | BA8: Máy Bơm, Rửa Khung lụa | BB8: Thước Đo Laser | BC8: Máy Khắc Laser | BD8: Tủ Sấy Khung Lụa | BE8: Máy CDI | BF8: Máy Revo | BG8: Máy Cello Ngang | BH8: Máy Rút Dây Cello | BI8: Máy Rút Mandrel | BJ8: Máy Đo/Uốn Thẳng Mandrel | BK8: Máy Paragon | BL8: Máy Mài - Đánh Bóng | BM8: Máy Khắc Laser | BN8: Máy Cắt (Apple) | BO8: Máy Đo/Xác Định Điểm Cong | BP8: Máy Laser | BQ8: Sử Dụng Tool Arrow | BR8: Máy Cắt | BS8: Máy Mài | BT8: Máy Decal | BU8: Máy Ép Hashima | BV8: Máy Sheet | BW8: Máy Die Cut | BX8: Máy Mài - Đánh Bóng | BY8: Máy CDI | BZ8: Máy Cello Ngang | CA8: Lò Oven | CB8: Máy Rút Madrel | CC8: Máy Cắt Đầu KAYAK | CD8: Máy Cắt KAYAK | CE8: Máy Rút Dây Cello | CF8: Máy Phun Sơn | CG8: Máy Paragon | CH8: Máy Spine/Spine Finder | CI8: Máy Proof Load/Zone | CJ8: Cân Weight | CK8: Máy Đo OD | CL8: Máy Soi Đầu TIP-Apple | CM8: Bảng/Máy Đo Ortho Flex | CN8: Máy Frequency | CO8: Máy Bending Test | CP8: Máy Torque 1/2 | CQ8: Máy Auto Inspection Golf Shaft | CR8: Máy Đo Độ Bền Sơn | CS8: Máy Rubtest | CT8: Falling Sand | CU8: Máy Straightness 1/2 | CV8: Máy Đo Mandrell | CW8: Máy Khoan Bàn / Phay | CX8: Máy Mài Dao | CY8: Máy Tiện, Khoan | CZ8: NOTE
A9: 1 | B9: 4205 | C9: Hà Minh Tiến | D9: Materials | E9: 45659 | F9: ü | N9: ü | O9: ü | CZ9: =IF(COUNTIF(F9:CY9,"ü")<=0,0,1) -> 1 | DA9: Ok
A10: 2 | B10: 4249 | C10: Từ Văn Đua | D10: Material Golf | E10: 45770 | F10: ü | O10: ü | CZ10: =IF(COUNTIF(F10:CY10,"ü")<=0,0,1) -> 1 | DA10: Ok
A11: 3 | B11: 4094 | C11: Nguyễn Minh Vương | D11: Arrow Graphics | E11: 45807 | AC11: ü | AY11: ü | BR11: ü | BS11: ü | BT11: ü | CZ11: =IF(COUNTIF(F11:CY11,"ü")<=0,0,1) -> 1 | DA11: Ok
A12: 4 | B12: 4106 | C12: Nguyễn Hoàng Cầm | D12: MFG Apple | E12: 45442 | G12: ü | W12: ü | BE12: ü | BF12: ü | BG12: ü | BQ12: ü | CZ12: =IF(COUNTIF(F12:CY12,"ü")<=0,0,1) -> 1 | DA12: Ok
A13: 5 | B13: 4257 | C13: Nguyễn Văn Lợi | D13: MFG Apple | E13: 45807 | G13: ü | AH13: ü | BH13: ü | BI13: ü | BJ13: ü | BK13: ü | CZ13: =IF(COUNTIF(F13:CY13,"ü")<=0,0,1) -> 1 | DA13: Ok
A14: 6 | B14: 5226 | C14: Nguyễn Văn Đạt | D14: QC Apple | E14: 45442 | CH14: ü | CI14: ü | CJ14: ü | CK14: ü | CZ14: =IF(COUNTIF(F14:CY14,"ü")<=0,0,1) -> 1 | DA14: Ok
A15: 7 | B15: 3203 | C15: Đặng Văn Toàn | D15: Paint Blending | E15: 45770 | G15: ü | J15: ü | K15: ü | L15: ü | CZ15: =IF(COUNTIF(F15:CY15,"ü")<=0,0,1) -> 1 | DA15: Ok
A16: 8 | B16: 5135 | C16: Nguyễn Đặng Thiên Tứ | D16: Paint Blending | E16: 45896 | G16: ü | J16: ü | K16: ü | L16: ü | AO16: ü | AR16: ü | AS16: ü | CZ16: =IF(COUNTIF(F16:CY16,"ü")<=0,0,1) -> 1 | DA16: Ok
A17: 9 | B17: 1150 | C17: Phan Minh Khang | D17: Arrow QC Blank | E17: 45807 | CH17: ü | CI17: ü | CJ17: ü | CK17: ü | CL17: ü | CZ17: =IF(COUNTIF(F17:CY17,"ü")<=0,0,1) -> 1 | DA17: Ok
A18: 10 | B18: 4800 | C18: Trần Văn Hoài | D18: Arrow QC Blank | E18: 45807 | CH18: ü | CI18: ü | CJ18: ü | CK18: ü | CZ18: =IF(COUNTIF(F18:CY18,"ü")<=0,0,1) -> 1 | DA18: Ok
A19: 11 | B19: 4973 | C19: Lê Thị Tâm | D19: Arrow QC Blank | E19: 45442 | CH19: ü | CI19: ü | CJ19: ü | CK19: ü | CZ19: =IF(COUNTIF(F19:CY19,"ü")<=0,0,1) -> 1 | DA19: Ok
A20: 12 | B20: 5261 | C20: Nguyễn Ngọc Như Ý | D20: Arrow QC Blank | E20: 45717 | CH20: ü | CI20: ü | CJ20: ü | CK20: ü | CL20: ü | CZ20: =IF(COUNTIF(F20:CY20,"ü")<=0,0,1) -> 1 | DA20: Ok
A21: 13 | B21: 5154 | C21: Huỳnh Thị Khả Vi | D21: Arrow QC Blank | E21: 45442 | CH21: ü | CI21: ü | CJ21: ü | CK21: ü | CZ21: =IF(COUNTIF(F21:CY21,"ü")<=0,0,1) -> 1 | DA21: Ok
A22: 14 | B22: 5059 | C22: Nguyễn Văn Chất | D22: Arrow QC Blank | E22: 45442 | CH22: ü | CI22: ü | CJ22: ü | CK22: ü | CL22: ü | CZ22: =IF(COUNTIF(F22:CY22,"ü")<=0,0,1) -> 1 | DA22: Ok
A23: 15 | B23: 0405 | C23: Đặng Hữu Thế | D23: Golf QC Blank | E23: 45669 | G23: ü | AN23: ü | CJ23: ü | CK23: ü | CM23: ü | CN23: ü | CO23: ü | CP23: ü | CQ23: ü | CU23: ü | CZ23: =IF(COUNTIF(F23:CY23,"ü")<=0,0,1) -> 1 | DA23: Ok
A24: 16 | B24: 4409 | C24: Nguyễn Thị Quỳnh Mai | D24: Golf QC Blank | E24: 45669 | G24: ü | AN24: ü | CJ24: ü | CK24: ü | CM24: ü | CN24: ü | CO24: ü | CP24: ü | CQ24: ü | CU24: ü | CZ24: =IF(COUNTIF(F24:CY24,"ü")<=0,0,1) -> 1 | DA24: Ok
A25: 17 | B25: 5150 | C25: Lê Trung Tính | D25: Golf QC Decorated | E25: 45386 | AN25: ü | CJ25: ü | CK25: ü | CM25: ü | CN25: ü | CP25: ü | CU25: ü | CZ25: =IF(COUNTIF(F25:CY25,"ü")<=0,0,1) -> 1 | DA25: Ok
A26: 18 | B26: 4347 | C26: Lê Công Thành | D26: Golf QC Blank | E26: 45659 | AN26: ü | CJ26: ü | CK26: ü | CM26: ü | CN26: ü | CP26: ü | CU26: ü | CZ26: =IF(COUNTIF(F26:CY26,"ü")<=0,0,1) -> 1 | DA26: Ok
A27: 19 | B27: 4795 | C27: Phan Hải Âu | D27: Golf QC Blank | E27: 45403 | CJ27: ü | CK27: ü | CM27: ü | CN27: ü | CU27: ü | CZ27: =IF(COUNTIF(F27:CY27,"ü")<=0,0,1) -> 1 | DA27: Ok
A28: 20 | B28: 4510 | C28: Lữ Minh Tiến | D28: Golf QC Blank | E28: 45666 | G28: ü | AN28: ü | CJ28: ü | CK28: ü | CM28: ü | CN28: ü | CO28: ü | CP28: ü | CQ28: ü | CU28: ü | CZ28: =IF(COUNTIF(F28:CY28,"ü")<=0,0,1) -> 1 | DA28: Ok
A29: 21 | B29: 4601 | C29: Lê Bá Đạt | D29: Golf QC Blank | E29: 45659 | G29: ü | BB29: ü | CJ29: ü | CK29: ü | CN29: ü | CU29: ü | CZ29: =IF(COUNTIF(F29:CY29,"ü")<=0,0,1) -> 1 | DA29: Ok
A30: 22 | B30: 5151 | C30: Trần Kiều Trân | D30: Golf QC Blank | E30: 45403 | AN30: ü | CJ30: ü | CK30: ü | CO30: ü | CQ30: ü | CU30: ü | CZ30: =IF(COUNTIF(F30:CY30,"ü")<=0,0,1) -> 1 | DA30: Ok
A31: 23 | B31: 39097 | C31: Nguyễn Văn Nhúm | D31: Golf QC Blank | E31: 45403 | AN31: ü | CJ31: ü | CK31: ü | CM31: ü | CN31: ü | CQ31: ü | CU31: ü | CZ31: =IF(COUNTIF(F31:CY31,"ü")<=0,0,1) -> 1 | DA31: Ok
A32: 24 | B32: 4715 | C32: Lê Văn Kiệt | D32: Golf QC Blank | E32: 45403 | AN32: ü | CJ32: ü | CK32: ü | CM32: ü | CN32: ü | CO32: ü | CP32: ü | CQ32: ü | CU32: ü | CZ32: =IF(COUNTIF(F32:CY32,"ü")<=0,0,1) -> 1 | DA32: Ok
A33: 25 | B33: 4882 | C33: Dương Thành Vũ | D33: Golf QC Blank | E33: 45669 | G33: ü | AN33: ü | CJ33: ü | CK33: ü | CM33: ü | CN33: ü | CO33: ü | CP33: ü | CQ33: ü | CU33: ü | CZ33: =IF(COUNTIF(F33:CY33,"ü")<=0,0,1) -> 1 | DA33: Ok
A34: 26 | B34: 4986 | C34: Nguyễn Chương Đức | D34: Golf QC Blank RW | E34: 45722 | G34: ü | BB34: ü | CJ34: ü | CK34: ü | CN34: ü | CR34: ü | CS34: ü | CT34: ü | CU34: ü | CZ34: =IF(COUNTIF(F34:CY34,"ü")<=0,0,1) -> 1 | DA34: Ok
A35: 27 | B35: 3566 | C35: Đỗ Thành Tài | D35: Golf QC Decorated | E35: 45403 | G35: ü | BB35: ü | CJ35: ü | CK35: ü | CN35: ü | CR35: ü | CS35: ü | CT35: ü | CU35: ü | CZ35: =IF(COUNTIF(F35:CY35,"ü")<=0,0,1) -> 1 | DA35: Ok
A36: 28 | B36: 4297 | C36: Lê Thị Hương | D36: Golf QC Decorated | E36: 45403 | G36: ü | CJ36: ü | CK36: ü | CN36: ü | CR36: ü | CS36: ü | CT36: ü | CU36: ü | CZ36: =IF(COUNTIF(F36:CY36,"ü")<=0,0,1) -> 1 | DA36: Ok
A37: 29 | B37: 4802 | C37: Lê Tấn Gạo | D37: Golf QC Decorated | E37: 45669 | G37: ü | BB37: ü | CJ37: ü | CK37: ü | CN37: ü | CS37: ü | CT37: ü | CU37: ü | CZ37: =IF(COUNTIF(F37:CY37,"ü")<=0,0,1) -> 1 | DA37: Ok
A38: 30 | B38: 4855 | C38: Dương Hoàng Vủ | D38: Golf QC Decorated | E38: 45659 | AN38: ü | CJ38: ü | CK38: ü | CM38: ü | CN38: ü | CO38: ü | CP38: ü | CQ38: ü | CU38: ü | CZ38: =IF(COUNTIF(F38:CY38,"ü")<=0,0,1) -> 1 | DA38: Ok
A39: 31 | B39: 5306 | C39: Nguyễn Quốc Kiệt | D39: Golf QC Blank | E39: 45386 | AN39: ü | CJ39: ü | CK39: ü | CM39: ü | CN39: ü | CP39: ü | CQ39: ü | CU39: ü | CZ39: =IF(COUNTIF(F39:CY39,"ü")<=0,0,1) -> 1 | DA39: Ok
A40: 32 | B40: 5026 | C40: Tô Văn Đức | D40: Golf QC Decorated | E40: 45659 | AN40: ü | CJ40: ü | CK40: ü | CM40: ü | CN40: ü | CO40: ü | CP40: ü | CQ40: ü | CU40: ü | CZ40: =IF(COUNTIF(F40:CY40,"ü")<=0,0,1) -> 1 | DA40: Ok
A41: 33 | B41: 4505 | C41: Nguyễn Văn Thắng | D41: Golf QC Decorated | E41: 45659 | AN41: ü | CJ41: ü | CK41: ü | CM41: ü | CN41: ü | CP41: ü | CQ41: ü | CU41: ü | CZ41: =IF(COUNTIF(F41:CY41,"ü")<=0,0,1) -> 1 | DA41: Ok
...

Sheet Summary
B1: TỔNG HỢP TÌNH TRẠNG CHỨNG NHẬN VẬN HÀNH
B2: Date Update: 06/10/2026
B4: BỘ PHẬN | C4: TỔNG HẠNG MỤC | D4: TỔNG NHÂN SỰ | E4: ĐỦ ĐIỀU KIỆN | F4: THIẾU CHỨNG NHẬN | G4: TỶ LỆ TUÂN THỦ
B5: Golf Cutting | C5: =COUNTA(G_Cutting!$H$6:$S$6) -> 12 | D5: =COUNTA(G_Cutting!$C$7:$C$76) -> 67 | E5: =COUNTIF(G_Cutting!$T:$T,"đủ điều kiện") -> 67 | F5: =D5-E5 -> 0 | G5: =E5/D5 -> 1
B6: Golf Rolling | C6: =COUNTA(G_Rolling!$H$6:$U$6) -> 14 | D6: =COUNTA(G_Rolling!$C$7:$C$153) -> 144 | E6: =COUNTIF(G_Rolling!$V:$V,"đủ điều kiện") -> 138 | F6: =D6-E6 -> 6 | G6: =E6/D6 -> 0.95833333
B7: Golf Finishing | C7: =COUNTA(G_Finishing!$H$6:$S$6) -> 12 | D7: =COUNTA(G_Finishing!$C$7:$C$53) -> 47 | E7: =COUNTIF(G_Finishing!$T:$T,"đủ điều kiện") -> 47 | F7: =D7-E7 -> 0 | G7: =E7/D7 -> 1
B8: Golf Buffing | C8: =COUNTA(G_Buffing!$H$6:$S$6) -> 12 | D8: =COUNTA(G_Buffing!$C$7:$C$52) -> 45 | E8: =COUNTIF(G_Buffing!$T:$T,"đủ điều kiện") -> 45 | F8: =D8-E8 -> 0 | G8: =E8/D8 -> 1
B9: Golf Dipping | C9: =COUNTA(G_Dipping!$H$6:$Q$6) -> 10 | D9: =COUNTA(G_Dipping!$C$7:$C$82) -> 74 | E9: =COUNTIF(G_Dipping!$R:$R,"đủ điều kiện") -> 74 | F9: =D9-E9 -> 0 | G9: =E9/D9 -> 1
B10: Golf Graphics | C10: =COUNTA(G_Graphics!$H$6:$R$6) -> 11 | D10: =COUNTA(G_Graphics!$C$7:$C$85) -> 77 | E10: =COUNTIF(G_Graphics!$S:$S,"đủ điều kiện") -> 74 | F10: =D10-E10 -> 3 | G10: =E10/D10 -> 0.96103896
B11: Arrow Blank | C11: =COUNTA(A_Blank!$H$6:$Z$6) -> 19 | D11: =COUNTA(A_Blank!$C$7:$C$55) -> 49 | E11: =COUNTIF(A_Blank!$AA:$AA,"đủ điều kiện") -> 49 | F11: =D11-E11 -> 0 | G11: =E11/D11 -> 1
B12: Arrow Graphics | C12: =COUNTA(A_Graphics!$H$6:$N$6) -> 7 | D12: =COUNTA(A_Graphics!$C$7:$C$40) -> 33 | E12: =COUNTIF(A_Graphics!$O:$O,"đủ điều kiện") -> 33 | F12: =D12-E12 -> 0 | G12: =E12/D12 -> 1
B13: Kayak | C13: =COUNTA(Kayak!$H$6:$Z$6) -> 19 | D13: =COUNTA(Kayak!$C$7:$C$22) -> 16 | E13: =COUNTIF(Kayak!$AA:$AA,"đủ điều kiện") -> 16 | F13: =D13-E13 -> 0 | G13: =E13/D13 -> 1
B15: BỘ PHẬN | C15: CHƯA ĐÀO TẠO | D15: ĐANG ĐÀO TẠO | E15: CHỜ ĐÁNH GIÁ | F15: CHỜ CẤP THẺ CNVH | G15: ĐÁNH GIÁ LẠI
B16: Golf Cutting | C16: =COUNTIF(G_Cutting!$U:$U,Summary!C$15) -> 0 | D16: =COUNTIF(G_Cutting!$U:$U,Summary!D$15) -> 0 | E16: =COUNTIF(G_Cutting!$U:$U,Summary!E$15) -> 0 | F16: =COUNTIF(G_Cutting!$U:$U,Summary!F$15) -> 0 | G16: =COUNTIF(G_Cutting!$U:$U,Summary!G$15) -> 0
B17: Golf Rolling | C17: =COUNTIF(G_Rolling!$W:$W,Summary!C$15) -> 0 | D17: =COUNTIF(G_Rolling!$W:$W,Summary!D$15) -> 6 | E17: =COUNTIF(G_Rolling!$W:$W,Summary!E$15) -> 0 | F17: =COUNTIF(G_Rolling!$W:$W,Summary!F$15) -> 0 | G17: =COUNTIF(G_Rolling!$W:$W,Summary!G$15) -> 0
B18: Golf Finishing | C18: =COUNTIF(G_Finishing!$U:$U,Summary!C$15) -> 0 | D18: =COUNTIF(G_Finishing!$U:$U,Summary!D$15) -> 0 | E18: =COUNTIF(G_Finishing!$U:$U,Summary!E$15) -> 0 | F18: =COUNTIF(G_Finishing!$U:$U,Summary!F$15) -> 0 | G18: =COUNTIF(G_Finishing!$U:$U,Summary!G$15) -> 0
B19: Golf Buffing | C19: =COUNTIF(G_Buffing!$U:$U,Summary!C$15) -> 0 | D19: =COUNTIF(G_Buffing!$U:$U,Summary!D$15) -> 0 | E19: =COUNTIF(G_Buffing!$U:$U,Summary!E$15) -> 0 | F19: =COUNTIF(G_Buffing!$U:$U,Summary!F$15) -> 0 | G19: =COUNTIF(G_Buffing!$U:$U,Summary!G$15) -> 0
B20: Golf Dipping | C20: =COUNTIF(G_Dipping!$S:$S,Summary!C$15) -> 0 | D20: =COUNTIF(G_Dipping!$S:$S,Summary!D$15) -> 0 | E20: =COUNTIF(G_Dipping!$S:$S,Summary!E$15) -> 0 | F20: =COUNTIF(G_Dipping!$S:$S,Summary!F$15) -> 0 | G20: =COUNTIF(G_Dipping!$S:$S,Summary!G$15) -> 0
B21: Golf Graphics | C21: =COUNTIF(G_Graphics!$T:$T,Summary!C$15) -> 0 | D21: =COUNTIF(G_Graphics!$T:$T,Summary!D$15) -> 1 | E21: =COUNTIF(G_Graphics!$T:$T,Summary!E$15) -> 0 | F21: =COUNTIF(G_Graphics!$T:$T,Summary!F$15) -> 0 | G21: =COUNTIF(G_Graphics!$T:$T,Summary!G$15) -> 2
B22: Arrow Blank | C22: =COUNTIF(A_Blank!$AB:$AB,Summary!C$15) -> 0 | D22: =COUNTIF(A_Blank!$AB:$AB,Summary!D$15) -> 0 | E22: =COUNTIF(A_Blank!$AB:$AB,Summary!E$15) -> 0 | F22: =COUNTIF(A_Blank!$AB:$AB,Summary!F$15) -> 0 | G22: =COUNTIF(A_Blank!$AB:$AB,Summary!G$15) -> 0
B23: Arrow Graphics | C23: =COUNTIF(A_Graphics!$P:$P,Summary!C$15) -> 0 | D23: =COUNTIF(A_Graphics!$P:$P,Summary!D$15) -> 0 | E23: =COUNTIF(A_Graphics!$P:$P,Summary!E$15) -> 0 | F23: =COUNTIF(A_Graphics!$P:$P,Summary!F$15) -> 0 | G23: =COUNTIF(A_Graphics!$P:$P,Summary!G$15) -> 0
B24: Kayak | C24: =COUNTIF(Kayak!$AB:$AB,Summary!C$15) -> 0 | D24: =COUNTIF(Kayak!$AB:$AB,Summary!D$15) -> 0 | E24: =COUNTIF(Kayak!$AB:$AB,Summary!E$15) -> 0 | F24: =COUNTIF(Kayak!$AB:$AB,Summary!F$15) -> 0 | G24: =COUNTIF(Kayak!$AB:$AB,Summary!G$15) -> 0

Sheet Data
A1: Week | B1: Ngày đánh giá | C1: G_Cutting | D1: G_Rolling | E1: G_Finishing | F1: G_Buffing | G1: G_Dipping | H1: G_Graphics | I1: A_Blank | J1: A_Graphics | K1: Kayak | M1: Week | N1: G_Cutting | O1: G_Rolling | P1: G_Finishing | Q1: G_Buffing | R1: G_Dipping | S1: G_Graphics | T1: A_Blank | U1: A_Graphics | V1: Kayak | W1: Total
A2: =TEXT(B2,"yyyy") & "-T" & TEXT(MONTH(B2),"00") -> 2025-T07 | B2: {=_xlfn._xlws.SORT(_xlfn.UNIQUE(_xlfn._xlws.FILTER(_xlfn.VSTACK(G_Cutting!G7:G999,G_Rolling!G7:G991,G_Finishing!G7:G998,G_Buffing!G7:G1000,G_Dipping!G7:G1008,G_Graphics!G7:G1002,A_Blank!G7:G55,A_Graphics!G7:G998,Kayak!G7:G995),_xlfn.VSTACK(G_Cutting!G7:G999,G_Rolling!G7:G991,G_Finishing!G7:G998,G_Buffing!G7:G1000,G_Dipping!G7:G1008,G_Graphics!G7:G1002,A_Blank!G7:G55,A_Graphics!G7:G998,Kayak!G7:G995)<>"")))} -> 45858 | C2: =COUNTIFS(INDIRECT(C$1 & "!$G$6:$G$1000"),$B2) -> 0 | D2: =COUNTIFS(INDIRECT(D$1 & "!$G$6:$G$1000"),$B2) -> 1 | E2: =COUNTIFS(INDIRECT(E$1 & "!$G$6:$G$1000"),$B2) -> 0 | F2: =COUNTIFS(INDIRECT(F$1 & "!$G$6:$G$1000"),$B2) -> 0 | G2: =COUNTIFS(INDIRECT(G$1 & "!$G$6:$G$1000"),$B2) -> 0 | H2: =COUNTIFS(INDIRECT(H$1 & "!$G$6:$G$1000"),$B2) -> 0 | I2: =COUNTIFS(INDIRECT(I$1 & "!$G$6:$G$1000"),$B2) -> 0 | J2: =COUNTIFS(INDIRECT(J$1 & "!$G$6:$G$1000"),$B2) -> 0 | K2: =COUNTIFS(INDIRECT(K$1 & "!$G$6:$G$1000"),$B2) -> 0 | M2: {=_xlfn._xlws.SORT(_xlfn.UNIQUE(A2:A86))} -> 2025-T07 | N2: =_xlfn.LET(_xlpm.v,SUMIFS(C:C,$A:$A,$M2),IF(_xlpm.v=0,"",_xlpm.v)) | O2: =_xlfn.LET(_xlpm.v,SUMIFS(D:D,$A:$A,$M2),IF(_xlpm.v=0,"",_xlpm.v)) -> 2 | P2: =_xlfn.LET(_xlpm.v,SUMIFS(E:E,$A:$A,$M2),IF(_xlpm.v=0,"",_xlpm.v)) -> 1 | Q2: =_xlfn.LET(_xlpm.v,SUMIFS(F:F,$A:$A,$M2),IF(_xlpm.v=0,"",_xlpm.v)) | R2: =_xlfn.LET(_xlpm.v,SUMIFS(G:G,$A:$A,$M2),IF(_xlpm.v=0,"",_xlpm.v)) | S2: =_xlfn.LET(_xlpm.v,SUMIFS(H:H,$A:$A,$M2),IF(_xlpm.v=0,"",_xlpm.v)) | T2: =_xlfn.LET(_xlpm.v,SUMIFS(I:I,$A:$A,$M2),IF(_xlpm.v=0,"",_xlpm.v)) | U2: =_xlfn.LET(_xlpm.v,SUMIFS(J:J,$A:$A,$M2),IF(_xlpm.v=0,"",_xlpm.v)) | V2: =_xlfn.LET(_xlpm.v,SUMIFS(K:K,$A:$A,$M2),IF(_xlpm.v=0,"",_xlpm.v)) | W2: =SUM(N2:V2) -> 3
A3: =TEXT(B3,"yyyy") & "-T" & TEXT(MONTH(B3),"00") -> 2025-T07 | B3: 45866 | C3: =COUNTIFS(INDIRECT(C$1 & "!$G$6:$G$1000"),$B3) -> 0 | D3: =COUNTIFS(INDIRECT(D$1 & "!$G$6:$G$1000"),$B3) -> 1 | E3: =COUNTIFS(INDIRECT(E$1 & "!$G$6:$G$1000"),$B3) -> 0 | F3: =COUNTIFS(INDIRECT(F$1 & "!$G$6:$G$1000"),$B3) -> 0 | G3: =COUNTIFS(INDIRECT(G$1 & "!$G$6:$G$1000"),$B3) -> 0 | H3: =COUNTIFS(INDIRECT(H$1 & "!$G$6:$G$1000"),$B3) -> 0 | I3: =COUNTIFS(INDIRECT(I$1 & "!$G$6:$G$1000"),$B3) -> 0 | J3: =COUNTIFS(INDIRECT(J$1 & "!$G$6:$G$1000"),$B3) -> 0 | K3: =COUNTIFS(INDIRECT(K$1 & "!$G$6:$G$1000"),$B3) -> 0 | M3: 2025-T08 | N3: =_xlfn.LET(_xlpm.v,SUMIFS(C:C,$A:$A,$M3),IF(_xlpm.v=0,"",_xlpm.v)) | O3: =_xlfn.LET(_xlpm.v,SUMIFS(D:D,$A:$A,$M3),IF(_xlpm.v=0,"",_xlpm.v)) -> 1 | P3: =_xlfn.LET(_xlpm.v,SUMIFS(E:E,$A:$A,$M3),IF(_xlpm.v=0,"",_xlpm.v)) | Q3: =_xlfn.LET(_xlpm.v,SUMIFS(F:F,$A:$A,$M3),IF(_xlpm.v=0,"",_xlpm.v)) | R3: =_xlfn.LET(_xlpm.v,SUMIFS(G:G,$A:$A,$M3),IF(_xlpm.v=0,"",_xlpm.v)) | S3: =_xlfn.LET(_xlpm.v,SUMIFS(H:H,$A:$A,$M3),IF(_xlpm.v=0,"",_xlpm.v)) | T3: =_xlfn.LET(_xlpm.v,SUMIFS(I:I,$A:$A,$M3),IF(_xlpm.v=0,"",_xlpm.v)) | U3: =_xlfn.LET(_xlpm.v,SUMIFS(J:J,$A:$A,$M3),IF(_xlpm.v=0,"",_xlpm.v)) | V3: =_xlfn.LET(_xlpm.v,SUMIFS(K:K,$A:$A,$M3),IF(_xlpm.v=0,"",_xlpm.v)) | W3: =SUM(N3:V3) -> 1
A4: =TEXT(B4,"yyyy") & "-T" & TEXT(MONTH(B4),"00") -> 2025-T07 | B4: 45869 | C4: =COUNTIFS(INDIRECT(C$1 & "!$G$6:$G$1000"),$B4) -> 0 | D4: =COUNTIFS(INDIRECT(D$1 & "!$G$6:$G$1000"),$B4) -> 0 | E4: =COUNTIFS(INDIRECT(E$1 & "!$G$6:$G$1000"),$B4) -> 1 | F4: =COUNTIFS(INDIRECT(F$1 & "!$G$6:$G$1000"),$B4) -> 0 | G4: =COUNTIFS(INDIRECT(G$1 & "!$G$6:$G$1000"),$B4) -> 0 | H4: =COUNTIFS(INDIRECT(H$1 & "!$G$6:$G$1000"),$B4) -> 0 | I4: =COUNTIFS(INDIRECT(I$1 & "!$G$6:$G$1000"),$B4) -> 0 | J4: =COUNTIFS(INDIRECT(J$1 & "!$G$6:$G$1000"),$B4) -> 0 | K4: =COUNTIFS(INDIRECT(K$1 & "!$G$6:$G$1000"),$B4) -> 0 | M4: 2025-T10 | N4: =_xlfn.LET(_xlpm.v,SUMIFS(C:C,$A:$A,$M4),IF(_xlpm.v=0,"",_xlpm.v)) | O4: =_xlfn.LET(_xlpm.v,SUMIFS(D:D,$A:$A,$M4),IF(_xlpm.v=0,"",_xlpm.v)) -> 2 | P4: =_xlfn.LET(_xlpm.v,SUMIFS(E:E,$A:$A,$M4),IF(_xlpm.v=0,"",_xlpm.v)) -> 2 | Q4: =_xlfn.LET(_xlpm.v,SUMIFS(F:F,$A:$A,$M4),IF(_xlpm.v=0,"",_xlpm.v)) -> 3 | R4: =_xlfn.LET(_xlpm.v,SUMIFS(G:G,$A:$A,$M4),IF(_xlpm.v=0,"",_xlpm.v)) -> 3 | S4: =_xlfn.LET(_xlpm.v,SUMIFS(H:H,$A:$A,$M4),IF(_xlpm.v=0,"",_xlpm.v)) | T4: =_xlfn.LET(_xlpm.v,SUMIFS(I:I,$A:$A,$M4),IF(_xlpm.v=0,"",_xlpm.v)) | U4: =_xlfn.LET(_xlpm.v,SUMIFS(J:J,$A:$A,$M4),IF(_xlpm.v=0,"",_xlpm.v)) | V4: =_xlfn.LET(_xlpm.v,SUMIFS(K:K,$A:$A,$M4),IF(_xlpm.v=0,"",_xlpm.v)) | W4: =SUM(N4:V4) -> 10
A5: =TEXT(B5,"yyyy") & "-T" & TEXT(MONTH(B5),"00") -> 2025-T08 | B5: 45892 | C5: =COUNTIFS(INDIRECT(C$1 & "!$G$6:$G$1000"),$B5) -> 0 | D5: =COUNTIFS(INDIRECT(D$1 & "!$G$6:$G$1000"),$B5) -> 1 | E5: =COUNTIFS(INDIRECT(E$1 & "!$G$6:$G$1000"),$B5) -> 0 | F5: =COUNTIFS(INDIRECT(F$1 & "!$G$6:$G$1000"),$B5) -> 0 | G5: =COUNTIFS(INDIRECT(G$1 & "!$G$6:$G$1000"),$B5) -> 0 | H5: =COUNTIFS(INDIRECT(H$1 & "!$G$6:$G$1000"),$B5) -> 0 | I5: =COUNTIFS(INDIRECT(I$1 & "!$G$6:$G$1000"),$B5) -> 0 | J5: =COUNTIFS(INDIRECT(J$1 & "!$G$6:$G$1000"),$B5) -> 0 | K5: =COUNTIFS(INDIRECT(K$1 & "!$G$6:$G$1000"),$B5) -> 0 | M5: 2025-T11 | N5: =_xlfn.LET(_xlpm.v,SUMIFS(C:C,$A:$A,$M5),IF(_xlpm.v=0,"",_xlpm.v)) -> 1 | O5: =_xlfn.LET(_xlpm.v,SUMIFS(D:D,$A:$A,$M5),IF(_xlpm.v=0,"",_xlpm.v)) -> 6 | P5: =_xlfn.LET(_xlpm.v,SUMIFS(E:E,$A:$A,$M5),IF(_xlpm.v=0,"",_xlpm.v)) | Q5: =_xlfn.LET(_xlpm.v,SUMIFS(F:F,$A:$A,$M5),IF(_xlpm.v=0,"",_xlpm.v)) | R5: =_xlfn.LET(_xlpm.v,SUMIFS(G:G,$A:$A,$M5),IF(_xlpm.v=0,"",_xlpm.v)) | S5: =_xlfn.LET(_xlpm.v,SUMIFS(H:H,$A:$A,$M5),IF(_xlpm.v=0,"",_xlpm.v)) -> 1 | T5: =_xlfn.LET(_xlpm.v,SUMIFS(I:I,$A:$A,$M5),IF(_xlpm.v=0,"",_xlpm.v)) | U5: =_xlfn.LET(_xlpm.v,SUMIFS(J:J,$A:$A,$M5),IF(_xlpm.v=0,"",_xlpm.v)) | V5: =_xlfn.LET(_xlpm.v,SUMIFS(K:K,$A:$A,$M5),IF(_xlpm.v=0,"",_xlpm.v)) | W5: =SUM(N5:V5) -> 8
A6: =TEXT(B6,"yyyy") & "-T" & TEXT(MONTH(B6),"00") -> 2025-T10 | B6: 45937 | C6: =COUNTIFS(INDIRECT(C$1 & "!$G$6:$G$1000"),$B6) -> 0 | D6: =COUNTIFS(INDIRECT(D$1 & "!$G$6:$G$1000"),$B6) -> 0 | E6: =COUNTIFS(INDIRECT(E$1 & "!$G$6:$G$1000"),$B6) -> 1 | F6: =COUNTIFS(INDIRECT(F$1 & "!$G$6:$G$1000"),$B6) -> 0 | G6: =COUNTIFS(INDIRECT(G$1 & "!$G$6:$G$1000"),$B6) -> 0 | H6: =COUNTIFS(INDIRECT(H$1 & "!$G$6:$G$1000"),$B6) -> 0 | I6: =COUNTIFS(INDIRECT(I$1 & "!$G$6:$G$1000"),$B6) -> 0 | J6: =COUNTIFS(INDIRECT(J$1 & "!$G$6:$G$1000"),$B6) -> 0 | K6: =COUNTIFS(INDIRECT(K$1 & "!$G$6:$G$1000"),$B6) -> 0 | M6: 2025-T12 | N6: =_xlfn.LET(_xlpm.v,SUMIFS(C:C,$A:$A,$M6),IF(_xlpm.v=0,"",_xlpm.v)) -> 8 | O6: =_xlfn.LET(_xlpm.v,SUMIFS(D:D,$A:$A,$M6),IF(_xlpm.v=0,"",_xlpm.v)) -> 3 | P6: =_xlfn.LET(_xlpm.v,SUMIFS(E:E,$A:$A,$M6),IF(_xlpm.v=0,"",_xlpm.v)) -> 3 | Q6: =_xlfn.LET(_xlpm.v,SUMIFS(F:F,$A:$A,$M6),IF(_xlpm.v=0,"",_xlpm.v)) -> 8 | R6: =_xlfn.LET(_xlpm.v,SUMIFS(G:G,$A:$A,$M6),IF(_xlpm.v=0,"",_xlpm.v)) -> 2 | S6: =_xlfn.LET(_xlpm.v,SUMIFS(H:H,$A:$A,$M6),IF(_xlpm.v=0,"",_xlpm.v)) | T6: =_xlfn.LET(_xlpm.v,SUMIFS(I:I,$A:$A,$M6),IF(_xlpm.v=0,"",_xlpm.v)) | U6: =_xlfn.LET(_xlpm.v,SUMIFS(J:J,$A:$A,$M6),IF(_xlpm.v=0,"",_xlpm.v)) | V6: =_xlfn.LET(_xlpm.v,SUMIFS(K:K,$A:$A,$M6),IF(_xlpm.v=0,"",_xlpm.v)) | W6: =SUM(N6:V6) -> 24
A7: =TEXT(B7,"yyyy") & "-T" & TEXT(MONTH(B7),"00") -> 2025-T10 | B7: 45945 | C7: =COUNTIFS(INDIRECT(C$1 & "!$G$6:$G$1000"),$B7) -> 0 | D7: =COUNTIFS(INDIRECT(D$1 & "!$G$6:$G$1000"),$B7) -> 0 | E7: =COUNTIFS(INDIRECT(E$1 & "!$G$6:$G$1000"),$B7) -> 1 | F7: =COUNTIFS(INDIRECT(F$1 & "!$G$6:$G$1000"),$B7) -> 0 | G7: =COUNTIFS(INDIRECT(G$1 & "!$G$6:$G$1000"),$B7) -> 0 | H7: =COUNTIFS(INDIRECT(H$1 & "!$G$6:$G$1000"),$B7) -> 0 | I7: =COUNTIFS(INDIRECT(I$1 & "!$G$6:$G$1000"),$B7) -> 0 | J7: =COUNTIFS(INDIRECT(J$1 & "!$G$6:$G$1000"),$B7) -> 0 | K7: =COUNTIFS(INDIRECT(K$1 & "!$G$6:$G$1000"),$B7) -> 0 | M7: 2026-T01 | N7: =_xlfn.LET(_xlpm.v,SUMIFS(C:C,$A:$A,$M7),IF(_xlpm.v=0,"",_xlpm.v)) | O7: =_xlfn.LET(_xlpm.v,SUMIFS(D:D,$A:$A,$M7),IF(_xlpm.v=0,"",_xlpm.v)) -> 3 | P7: =_xlfn.LET(_xlpm.v,SUMIFS(E:E,$A:$A,$M7),IF(_xlpm.v=0,"",_xlpm.v)) | Q7: =_xlfn.LET(_xlpm.v,SUMIFS(F:F,$A:$A,$M7),IF(_xlpm.v=0,"",_xlpm.v)) -> 1 | R7: =_xlfn.LET(_xlpm.v,SUMIFS(G:G,$A:$A,$M7),IF(_xlpm.v=0,"",_xlpm.v)) -> 2 | S7: =_xlfn.LET(_xlpm.v,SUMIFS(H:H,$A:$A,$M7),IF(_xlpm.v=0,"",_xlpm.v)) -> 2 | T7: =_xlfn.LET(_xlpm.v,SUMIFS(I:I,$A:$A,$M7),IF(_xlpm.v=0,"",_xlpm.v)) | U7: =_xlfn.LET(_xlpm.v,SUMIFS(J:J,$A:$A,$M7),IF(_xlpm.v=0,"",_xlpm.v)) | V7: =_xlfn.LET(_xlpm.v,SUMIFS(K:K,$A:$A,$M7),IF(_xlpm.v=0,"",_xlpm.v)) | W7: =SUM(N7:V7) -> 8
A8: =TEXT(B8,"yyyy") & "-T" & TEXT(MONTH(B8),"00") -> 2025-T10 | B8: 45948 | C8: =COUNTIFS(INDIRECT(C$1 & "!$G$6:$G$1000"),$B8) -> 0 | D8: =COUNTIFS(INDIRECT(D$1 & "!$G$6:$G$1000"),$B8) -> 0 | E8: =COUNTIFS(INDIRECT(E$1 & "!$G$6:$G$1000"),$B8) -> 0 | F8: =COUNTIFS(INDIRECT(F$1 & "!$G$6:$G$1000"),$B8) -> 0 | G8: =COUNTIFS(INDIRECT(G$1 & "!$G$6:$G$1000"),$B8) -> 3 | H8: =COUNTIFS(INDIRECT(H$1 & "!$G$6:$G$1000"),$B8) -> 0 | I8: =COUNTIFS(INDIRECT(I$1 & "!$G$6:$G$1000"),$B8) -> 0 | J8: =COUNTIFS(INDIRECT(J$1 & "!$G$6:$G$1000"),$B8) -> 0 | K8: =COUNTIFS(INDIRECT(K$1 & "!$G$6:$G$1000"),$B8) -> 0 | M8: 2026-T02 | N8: =_xlfn.LET(_xlpm.v,SUMIFS(C:C,$A:$A,$M8),IF(_xlpm.v=0,"",_xlpm.v)) -> 3 | O8: =_xlfn.LET(_xlpm.v,SUMIFS(D:D,$A:$A,$M8),IF(_xlpm.v=0,"",_xlpm.v)) -> 2 | P8: =_xlfn.LET(_xlpm.v,SUMIFS(E:E,$A:$A,$M8),IF(_xlpm.v=0,"",_xlpm.v)) | Q8: =_xlfn.LET(_xlpm.v,SUMIFS(F:F,$A:$A,$M8),IF(_xlpm.v=0,"",_xlpm.v)) | R8: =_xlfn.LET(_xlpm.v,SUMIFS(G:G,$A:$A,$M8),IF(_xlpm.v=0,"",_xlpm.v)) -> 2 | S8: =_xlfn.LET(_xlpm.v,SUMIFS(H:H,$A:$A,$M8),IF(_xlpm.v=0,"",_xlpm.v)) -> 1 | T8: =_xlfn.LET(_xlpm.v,SUMIFS(I:I,$A:$A,$M8),IF(_xlpm.v=0,"",_xlpm.v)) | U8: =_xlfn.LET(_xlpm.v,SUMIFS(J:J,$A:$A,$M8),IF(_xlpm.v=0,"",_xlpm.v)) | V8: =_xlfn.LET(_xlpm.v,SUMIFS(K:K,$A:$A,$M8),IF(_xlpm.v=0,"",_xlpm.v)) | W8: =SUM(N8:V8) -> 8
A9: =TEXT(B9,"yyyy") & "-T" & TEXT(MONTH(B9),"00") -> 2025-T10 | B9: 45950 | C9: =COUNTIFS(INDIRECT(C$1 & "!$G$6:$G$1000"),$B9) -> 0 | D9: =COUNTIFS(INDIRECT(D$1 & "!$G$6:$G$1000"),$B9) -> 0 | E9: =COUNTIFS(INDIRECT(E$1 & "!$G$6:$G$1000"),$B9) -> 0 | F9: =COUNTIFS(INDIRECT(F$1 & "!$G$6:$G$1000"),$B9) -> 1 | G9: =COUNTIFS(INDIRECT(G$1 & "!$G$6:$G$1000"),$B9) -> 0 | H9: =COUNTIFS(INDIRECT(H$1 & "!$G$6:$G$1000"),$B9) -> 0 | I9: =COUNTIFS(INDIRECT(I$1 & "!$G$6:$G$1000"),$B9) -> 0 | J9: =COUNTIFS(INDIRECT(J$1 & "!$G$6:$G$1000"),$B9) -> 0 | K9: =COUNTIFS(INDIRECT(K$1 & "!$G$6:$G$1000"),$B9) -> 0 | M9: 2026-T03 | N9: =_xlfn.LET(_xlpm.v,SUMIFS(C:C,$A:$A,$M9),IF(_xlpm.v=0,"",_xlpm.v)) -> 2 | O9: =_xlfn.LET(_xlpm.v,SUMIFS(D:D,$A:$A,$M9),IF(_xlpm.v=0,"",_xlpm.v)) -> 8 | P9: =_xlfn.LET(_xlpm.v,SUMIFS(E:E,$A:$A,$M9),IF(_xlpm.v=0,"",_xlpm.v)) -> 4 | Q9: =_xlfn.LET(_xlpm.v,SUMIFS(F:F,$A:$A,$M9),IF(_xlpm.v=0,"",_xlpm.v)) -> 1 | R9: =_xlfn.LET(_xlpm.v,SUMIFS(G:G,$A:$A,$M9),IF(_xlpm.v=0,"",_xlpm.v)) -> 7 | S9: =_xlfn.LET(_xlpm.v,SUMIFS(H:H,$A:$A,$M9),IF(_xlpm.v=0,"",_xlpm.v)) -> 4 | T9: =_xlfn.LET(_xlpm.v,SUMIFS(I:I,$A:$A,$M9),IF(_xlpm.v=0,"",_xlpm.v)) | U9: =_xlfn.LET(_xlpm.v,SUMIFS(J:J,$A:$A,$M9),IF(_xlpm.v=0,"",_xlpm.v)) | V9: =_xlfn.LET(_xlpm.v,SUMIFS(K:K,$A:$A,$M9),IF(_xlpm.v=0,"",_xlpm.v)) -> 1 | W9: =SUM(N9:V9) -> 27
A10: =TEXT(B10,"yyyy") & "-T" & TEXT(MONTH(B10),"00") -> 2025-T10 | B10: 45955 | C10: =COUNTIFS(INDIRECT(C$1 & "!$G$6:$G$1000"),$B10) -> 0 | D10: =COUNTIFS(INDIRECT(D$1 & "!$G$6:$G$1000"),$B10) -> 2 | E10: =COUNTIFS(INDIRECT(E$1 & "!$G$6:$G$1000"),$B10) -> 0 | F10: =COUNTIFS(INDIRECT(F$1 & "!$G$6:$G$1000"),$B10) -> 2 | G10: =COUNTIFS(INDIRECT(G$1 & "!$G$6:$G$1000"),$B10) -> 0 | H10: =COUNTIFS(INDIRECT(H$1 & "!$G$6:$G$1000"),$B10) -> 0 | I10: =COUNTIFS(INDIRECT(I$1 & "!$G$6:$G$1000"),$B10) -> 0 | J10: =COUNTIFS(INDIRECT(J$1 & "!$G$6:$G$1000"),$B10) -> 0 | K10: =COUNTIFS(INDIRECT(K$1 & "!$G$6:$G$1000"),$B10) -> 0 | M10: 2026-T04 | N10: =_xlfn.LET(_xlpm.v,SUMIFS(C:C,$A:$A,$M10),IF(_xlpm.v=0,"",_xlpm.v)) -> 21 | O10: =_xlfn.LET(_xlpm.v,SUMIFS(D:D,$A:$A,$M10),IF(_xlpm.v=0,"",_xlpm.v)) -> 27 | P10: =_xlfn.LET(_xlpm.v,SUMIFS(E:E,$A:$A,$M10),IF(_xlpm.v=0,"",_xlpm.v)) | Q10: =_xlfn.LET(_xlpm.v,SUMIFS(F:F,$A:$A,$M10),IF(_xlpm.v=0,"",_xlpm.v)) -> 7 | R10: =_xlfn.LET(_xlpm.v,SUMIFS(G:G,$A:$A,$M10),IF(_xlpm.v=0,"",_xlpm.v)) -> 6 | S10: =_xlfn.LET(_xlpm.v,SUMIFS(H:H,$A:$A,$M10),IF(_xlpm.v=0,"",_xlpm.v)) -> 5 | T10: =_xlfn.LET(_xlpm.v,SUMIFS(I:I,$A:$A,$M10),IF(_xlpm.v=0,"",_xlpm.v)) -> 10 | U10: =_xlfn.LET(_xlpm.v,SUMIFS(J:J,$A:$A,$M10),IF(_xlpm.v=0,"",_xlpm.v)) -> 6 | V10: =_xlfn.LET(_xlpm.v,SUMIFS(K:K,$A:$A,$M10),IF(_xlpm.v=0,"",_xlpm.v)) -> 8 | W10: =SUM(N10:V10) -> 90
A11: =TEXT(B11,"yyyy") & "-T" & TEXT(MONTH(B11),"00") -> 2025-T11 | B11: 45962 | C11: =COUNTIFS(INDIRECT(C$1 & "!$G$6:$G$1000"),$B11) -> 0 | D11: =COUNTIFS(INDIRECT(D$1 & "!$G$6:$G$1000"),$B11) -> 1 | E11: =COUNTIFS(INDIRECT(E$1 & "!$G$6:$G$1000"),$B11) -> 0 | F11: =COUNTIFS(INDIRECT(F$1 & "!$G$6:$G$1000"),$B11) -> 0 | G11: =COUNTIFS(INDIRECT(G$1 & "!$G$6:$G$1000"),$B11) -> 0 | H11: =COUNTIFS(INDIRECT(H$1 & "!$G$6:$G$1000"),$B11) -> 0 | I11: =COUNTIFS(INDIRECT(I$1 & "!$G$6:$G$1000"),$B11) -> 0 | J11: =COUNTIFS(INDIRECT(J$1 & "!$G$6:$G$1000"),$B11) -> 0 | K11: =COUNTIFS(INDIRECT(K$1 & "!$G$6:$G$1000"),$B11) -> 0 | M11: 2026-T05 | N11: =_xlfn.LET(_xlpm.v,SUMIFS(C:C,$A:$A,$M11),IF(_xlpm.v=0,"",_xlpm.v)) -> 2 | O11: =_xlfn.LET(_xlpm.v,SUMIFS(D:D,$A:$A,$M11),IF(_xlpm.v=0,"",_xlpm.v)) -> 6 | P11: =_xlfn.LET(_xlpm.v,SUMIFS(E:E,$A:$A,$M11),IF(_xlpm.v=0,"",_xlpm.v)) -> 3 | Q11: =_xlfn.LET(_xlpm.v,SUMIFS(F:F,$A:$A,$M11),IF(_xlpm.v=0,"",_xlpm.v)) -> 5 | R11: =_xlfn.LET(_xlpm.v,SUMIFS(G:G,$A:$A,$M11),IF(_xlpm.v=0,"",_xlpm.v)) -> 3 | S11: =_xlfn.LET(_xlpm.v,SUMIFS(H:H,$A:$A,$M11),IF(_xlpm.v=0,"",_xlpm.v)) -> 6 | T11: =_xlfn.LET(_xlpm.v,SUMIFS(I:I,$A:$A,$M11),IF(_xlpm.v=0,"",_xlpm.v)) -> 18 | U11: =_xlfn.LET(_xlpm.v,SUMIFS(J:J,$A:$A,$M11),IF(_xlpm.v=0,"",_xlpm.v)) -> 4 | V11: =_xlfn.LET(_xlpm.v,SUMIFS(K:K,$A:$A,$M11),IF(_xlpm.v=0,"",_xlpm.v)) -> 4 | W11: =SUM(N11:V11) -> 51
A12: =TEXT(B12,"yyyy") & "-T" & TEXT(MONTH(B12),"00") -> 2025-T11 | B12: 45975 | C12: =COUNTIFS(INDIRECT(C$1 & "!$G$6:$G$1000"),$B12) -> 0 | D12: =COUNTIFS(INDIRECT(D$1 & "!$G$6:$G$1000"),$B12) -> 5 | E12: =COUNTIFS(INDIRECT(E$1 & "!$G$6:$G$1000"),$B12) -> 0 | F12: =COUNTIFS(INDIRECT(F$1 & "!$G$6:$G$1000"),$B12) -> 0 | G12: =COUNTIFS(INDIRECT(G$1 & "!$G$6:$G$1000"),$B12) -> 0 | H12: =COUNTIFS(INDIRECT(H$1 & "!$G$6:$G$1000"),$B12) -> 0 | I12: =COUNTIFS(INDIRECT(I$1 & "!$G$6:$G$1000"),$B12) -> 0 | J12: =COUNTIFS(INDIRECT(J$1 & "!$G$6:$G$1000"),$B12) -> 0 | K12: =COUNTIFS(INDIRECT(K$1 & "!$G$6:$G$1000"),$B12) -> 0 | M12: 2026-T06 | N12: =_xlfn.LET(_xlpm.v,SUMIFS(C:C,$A:$A,$M12),IF(_xlpm.v=0,"",_xlpm.v)) -> 3 | O12: =_xlfn.LET(_xlpm.v,SUMIFS(D:D,$A:$A,$M12),IF(_xlpm.v=0,"",_xlpm.v)) | P12: =_xlfn.LET(_xlpm.v,SUMIFS(E:E,$A:$A,$M12),IF(_xlpm.v=0,"",_xlpm.v)) -> 2 | Q12: =_xlfn.LET(_xlpm.v,SUMIFS(F:F,$A:$A,$M12),IF(_xlpm.v=0,"",_xlpm.v)) -> 1 | R12: =_xlfn.LET(_xlpm.v,SUMIFS(G:G,$A:$A,$M12),IF(_xlpm.v=0,"",_xlpm.v)) | S12: =_xlfn.LET(_xlpm.v,SUMIFS(H:H,$A:$A,$M12),IF(_xlpm.v=0,"",_xlpm.v)) | T12: =_xlfn.LET(_xlpm.v,SUMIFS(I:I,$A:$A,$M12),IF(_xlpm.v=0,"",_xlpm.v)) -> 2 | U12: =_xlfn.LET(_xlpm.v,SUMIFS(J:J,$A:$A,$M12),IF(_xlpm.v=0,"",_xlpm.v)) -> 1 | V12: =_xlfn.LET(_xlpm.v,SUMIFS(K:K,$A:$A,$M12),IF(_xlpm.v=0,"",_xlpm.v)) | W12: =SUM(N12:V12) -> 9
A13: =TEXT(B13,"yyyy") & "-T" & TEXT(MONTH(B13),"00") -> 2025-T11 | B13: 45976 | C13: =COUNTIFS(INDIRECT(C$1 & "!$G$6:$G$1000"),$B13) -> 0 | D13: =COUNTIFS(INDIRECT(D$1 & "!$G$6:$G$1000"),$B13) -> 0 | E13: =COUNTIFS(INDIRECT(E$1 & "!$G$6:$G$1000"),$B13) -> 0 | F13: =COUNTIFS(INDIRECT(F$1 & "!$G$6:$G$1000"),$B13) -> 0 | G13: =COUNTIFS(INDIRECT(G$1 & "!$G$6:$G$1000"),$B13) -> 0 | H13: =COUNTIFS(INDIRECT(H$1 & "!$G$6:$G$1000"),$B13) -> 1 | I13: =COUNTIFS(INDIRECT(I$1 & "!$G$6:$G$1000"),$B13) -> 0 | J13: =COUNTIFS(INDIRECT(J$1 & "!$G$6:$G$1000"),$B13) -> 0 | K13: =COUNTIFS(INDIRECT(K$1 & "!$G$6:$G$1000"),$B13) -> 0 | N13: =_xlfn.LET(_xlpm.v,SUMIFS(C:C,$A:$A,$M13),IF(_xlpm.v=0,"",_xlpm.v)) | O13: =_xlfn.LET(_xlpm.v,SUMIFS(D:D,$A:$A,$M13),IF(_xlpm.v=0,"",_xlpm.v)) | P13: =_xlfn.LET(_xlpm.v,SUMIFS(E:E,$A:$A,$M13),IF(_xlpm.v=0,"",_xlpm.v)) | Q13: =_xlfn.LET(_xlpm.v,SUMIFS(F:F,$A:$A,$M13),IF(_xlpm.v=0,"",_xlpm.v)) | R13: =_xlfn.LET(_xlpm.v,SUMIFS(G:G,$A:$A,$M13),IF(_xlpm.v=0,"",_xlpm.v)) | S13: =_xlfn.LET(_xlpm.v,SUMIFS(H:H,$A:$A,$M13),IF(_xlpm.v=0,"",_xlpm.v)) | T13: =_xlfn.LET(_xlpm.v,SUMIFS(I:I,$A:$A,$M13),IF(_xlpm.v=0,"",_xlpm.v)) | U13: =_xlfn.LET(_xlpm.v,SUMIFS(J:J,$A:$A,$M13),IF(_xlpm.v=0,"",_xlpm.v)) | V13: =_xlfn.LET(_xlpm.v,SUMIFS(K:K,$A:$A,$M13),IF(_xlpm.v=0,"",_xlpm.v)) | W13: =SUM(N13:V13) -> 0
A14: =TEXT(B14,"yyyy") & "-T" & TEXT(MONTH(B14),"00") -> 2025-T11 | B14: 45979 | C14: =COUNTIFS(INDIRECT(C$1 & "!$G$6:$G$1000"),$B14) -> 1 | D14: =COUNTIFS(INDIRECT(D$1 & "!$G$6:$G$1000"),$B14) -> 0 | E14: =COUNTIFS(INDIRECT(E$1 & "!$G$6:$G$1000"),$B14) -> 0 | F14: =COUNTIFS(INDIRECT(F$1 & "!$G$6:$G$1000"),$B14) -> 0 | G14: =COUNTIFS(INDIRECT(G$1 & "!$G$6:$G$1000"),$B14) -> 0 | H14: =COUNTIFS(INDIRECT(H$1 & "!$G$6:$G$1000"),$B14) -> 0 | I14: =COUNTIFS(INDIRECT(I$1 & "!$G$6:$G$1000"),$B14) -> 0 | J14: =COUNTIFS(INDIRECT(J$1 & "!$G$6:$G$1000"),$B14) -> 0 | K14: =COUNTIFS(INDIRECT(K$1 & "!$G$6:$G$1000"),$B14) -> 0 | N14: =_xlfn.LET(_xlpm.v,SUMIFS(C:C,$A:$A,$M14),IF(_xlpm.v=0,"",_xlpm.v)) | O14: =_xlfn.LET(_xlpm.v,SUMIFS(D:D,$A:$A,$M14),IF(_xlpm.v=0,"",_xlpm.v)) | P14: =_xlfn.LET(_xlpm.v,SUMIFS(E:E,$A:$A,$M14),IF(_xlpm.v=0,"",_xlpm.v)) | Q14: =_xlfn.LET(_xlpm.v,SUMIFS(F:F,$A:$A,$M14),IF(_xlpm.v=0,"",_xlpm.v)) | R14: =_xlfn.LET(_xlpm.v,SUMIFS(G:G,$A:$A,$M14),IF(_xlpm.v=0,"",_xlpm.v)) | S14: =_xlfn.LET(_xlpm.v,SUMIFS(H:H,$A:$A,$M14),IF(_xlpm.v=0,"",_xlpm.v)) | T14: =_xlfn.LET(_xlpm.v,SUMIFS(I:I,$A:$A,$M14),IF(_xlpm.v=0,"",_xlpm.v)) | U14: =_xlfn.LET(_xlpm.v,SUMIFS(J:J,$A:$A,$M14),IF(_xlpm.v=0,"",_xlpm.v)) | V14: =_xlfn.LET(_xlpm.v,SUMIFS(K:K,$A:$A,$M14),IF(_xlpm.v=0,"",_xlpm.v)) | W14: =SUM(N14:V14) -> 0
A15: =TEXT(B15,"yyyy") & "-T" & TEXT(MONTH(B15),"00") -> 2025-T12 | B15: 45995 | C15: =COUNTIFS(INDIRECT(C$1 & "!$G$6:$G$1000"),$B15) -> 0 | D15: =COUNTIFS(INDIRECT(D$1 & "!$G$6:$G$1000"),$B15) -> 0 | E15: =COUNTIFS(INDIRECT(E$1 & "!$G$6:$G$1000"),$B15) -> 0 | F15: =COUNTIFS(INDIRECT(F$1 & "!$G$6:$G$1000"),$B15) -> 1 | G15: =COUNTIFS(INDIRECT(G$1 & "!$G$6:$G$1000"),$B15) -> 0 | H15: =COUNTIFS(INDIRECT(H$1 & "!$G$6:$G$1000"),$B15) -> 0 | I15: =COUNTIFS(INDIRECT(I$1 & "!$G$6:$G$1000"),$B15) -> 0 | J15: =COUNTIFS(INDIRECT(J$1 & "!$G$6:$G$1000"),$B15) -> 0 | K15: =COUNTIFS(INDIRECT(K$1 & "!$G$6:$G$1000"),$B15) -> 0 | N15: =_xlfn.LET(_xlpm.v,SUMIFS(C:C,$A:$A,$M15),IF(_xlpm.v=0,"",_xlpm.v)) | O15: =_xlfn.LET(_xlpm.v,SUMIFS(D:D,$A:$A,$M15),IF(_xlpm.v=0,"",_xlpm.v)) | P15: =_xlfn.LET(_xlpm.v,SUMIFS(E:E,$A:$A,$M15),IF(_xlpm.v=0,"",_xlpm.v)) | Q15: =_xlfn.LET(_xlpm.v,SUMIFS(F:F,$A:$A,$M15),IF(_xlpm.v=0,"",_xlpm.v)) | R15: =_xlfn.LET(_xlpm.v,SUMIFS(G:G,$A:$A,$M15),IF(_xlpm.v=0,"",_xlpm.v)) | S15: =_xlfn.LET(_xlpm.v,SUMIFS(H:H,$A:$A,$M15),IF(_xlpm.v=0,"",_xlpm.v)) | T15: =_xlfn.LET(_xlpm.v,SUMIFS(I:I,$A:$A,$M15),IF(_xlpm.v=0,"",_xlpm.v)) | U15: =_xlfn.LET(_xlpm.v,SUMIFS(J:J,$A:$A,$M15),IF(_xlpm.v=0,"",_xlpm.v)) | V15: =_xlfn.LET(_xlpm.v,SUMIFS(K:K,$A:$A,$M15),IF(_xlpm.v=0,"",_xlpm.v)) | W15: =SUM(N15:V15) -> 0
A16: =TEXT(B16,"yyyy") & "-T" & TEXT(MONTH(B16),"00") -> 2025-T12 | B16: 45998 | C16: =COUNTIFS(INDIRECT(C$1 & "!$G$6:$G$1000"),$B16) -> 1 | D16: =COUNTIFS(INDIRECT(D$1 & "!$G$6:$G$1000"),$B16) -> 0 | E16: =COUNTIFS(INDIRECT(E$1 & "!$G$6:$G$1000"),$B16) -> 0 | F16: =COUNTIFS(INDIRECT(F$1 & "!$G$6:$G$1000"),$B16) -> 5 | G16: =COUNTIFS(INDIRECT(G$1 & "!$G$6:$G$1000"),$B16) -> 0 | H16: =COUNTIFS(INDIRECT(H$1 & "!$G$6:$G$1000"),$B16) -> 0 | I16: =COUNTIFS(INDIRECT(I$1 & "!$G$6:$G$1000"),$B16) -> 0 | J16: =COUNTIFS(INDIRECT(J$1 & "!$G$6:$G$1000"),$B16) -> 0 | K16: =COUNTIFS(INDIRECT(K$1 & "!$G$6:$G$1000"),$B16) -> 0 | N16: =_xlfn.LET(_xlpm.v,SUMIFS(C:C,$A:$A,$M16),IF(_xlpm.v=0,"",_xlpm.v)) | O16: =_xlfn.LET(_xlpm.v,SUMIFS(D:D,$A:$A,$M16),IF(_xlpm.v=0,"",_xlpm.v)) | P16: =_xlfn.LET(_xlpm.v,SUMIFS(E:E,$A:$A,$M16),IF(_xlpm.v=0,"",_xlpm.v)) | Q16: =_xlfn.LET(_xlpm.v,SUMIFS(F:F,$A:$A,$M16),IF(_xlpm.v=0,"",_xlpm.v)) | R16: =_xlfn.LET(_xlpm.v,SUMIFS(G:G,$A:$A,$M16),IF(_xlpm.v=0,"",_xlpm.v)) | S16: =_xlfn.LET(_xlpm.v,SUMIFS(H:H,$A:$A,$M16),IF(_xlpm.v=0,"",_xlpm.v)) | T16: =_xlfn.LET(_xlpm.v,SUMIFS(I:I,$A:$A,$M16),IF(_xlpm.v=0,"",_xlpm.v)) | U16: =_xlfn.LET(_xlpm.v,SUMIFS(J:J,$A:$A,$M16),IF(_xlpm.v=0,"",_xlpm.v)) | V16: =_xlfn.LET(_xlpm.v,SUMIFS(K:K,$A:$A,$M16),IF(_xlpm.v=0,"",_xlpm.v)) | W16: =SUM(N16:V16) -> 0
A17: =TEXT(B17,"yyyy") & "-T" & TEXT(MONTH(B17),"00") -> 2025-T12 | B17: 46001 | C17: =COUNTIFS(INDIRECT(C$1 & "!$G$6:$G$1000"),$B17) -> 7 | D17: =COUNTIFS(INDIRECT(D$1 & "!$G$6:$G$1000"),$B17) -> 0 | E17: =COUNTIFS(INDIRECT(E$1 & "!$G$6:$G$1000"),$B17) -> 0 | F17: =COUNTIFS(INDIRECT(F$1 & "!$G$6:$G$1000"),$B17) -> 0 | G17: =COUNTIFS(INDIRECT(G$1 & "!$G$6:$G$1000"),$B17) -> 1 | H17: =COUNTIFS(INDIRECT(H$1 & "!$G$6:$G$1000"),$B17) -> 0 | I17: =COUNTIFS(INDIRECT(I$1 & "!$G$6:$G$1000"),$B17) -> 0 | J17: =COUNTIFS(INDIRECT(J$1 & "!$G$6:$G$1000"),$B17) -> 0 | K17: =COUNTIFS(INDIRECT(K$1 & "!$G$6:$G$1000"),$B17) -> 0 | N17: =_xlfn.LET(_xlpm.v,SUMIFS(C:C,$A:$A,$M17),IF(_xlpm.v=0,"",_xlpm.v)) | O17: =_xlfn.LET(_xlpm.v,SUMIFS(D:D,$A:$A,$M17),IF(_xlpm.v=0,"",_xlpm.v)) | P17: =_xlfn.LET(_xlpm.v,SUMIFS(E:E,$A:$A,$M17),IF(_xlpm.v=0,"",_xlpm.v)) | Q17: =_xlfn.LET(_xlpm.v,SUMIFS(F:F,$A:$A,$M17),IF(_xlpm.v=0,"",_xlpm.v)) | R17: =_xlfn.LET(_xlpm.v,SUMIFS(G:G,$A:$A,$M17),IF(_xlpm.v=0,"",_xlpm.v)) | S17: =_xlfn.LET(_xlpm.v,SUMIFS(H:H,$A:$A,$M17),IF(_xlpm.v=0,"",_xlpm.v)) | T17: =_xlfn.LET(_xlpm.v,SUMIFS(I:I,$A:$A,$M17),IF(_xlpm.v=0,"",_xlpm.v)) | U17: =_xlfn.LET(_xlpm.v,SUMIFS(J:J,$A:$A,$M17),IF(_xlpm.v=0,"",_xlpm.v)) | V17: =_xlfn.LET(_xlpm.v,SUMIFS(K:K,$A:$A,$M17),IF(_xlpm.v=0,"",_xlpm.v)) | W17: =SUM(N17:V17) -> 0
A18: =TEXT(B18,"yyyy") & "-T" & TEXT(MONTH(B18),"00") -> 2025-T12 | B18: 46003 | C18: =COUNTIFS(INDIRECT(C$1 & "!$G$6:$G$1000"),$B18) -> 0 | D18: =COUNTIFS(INDIRECT(D$1 & "!$G$6:$G$1000"),$B18) -> 3 | E18: =COUNTIFS(INDIRECT(E$1 & "!$G$6:$G$1000"),$B18) -> 0 | F18: =COUNTIFS(INDIRECT(F$1 & "!$G$6:$G$1000"),$B18) -> 0 | G18: =COUNTIFS(INDIRECT(G$1 & "!$G$6:$G$1000"),$B18) -> 0 | H18: =COUNTIFS(INDIRECT(H$1 & "!$G$6:$G$1000"),$B18) -> 0 | I18: =COUNTIFS(INDIRECT(I$1 & "!$G$6:$G$1000"),$B18) -> 0 | J18: =COUNTIFS(INDIRECT(J$1 & "!$G$6:$G$1000"),$B18) -> 0 | K18: =COUNTIFS(INDIRECT(K$1 & "!$G$6:$G$1000"),$B18) -> 0 | N18: =_xlfn.LET(_xlpm.v,SUMIFS(C:C,$A:$A,$M18),IF(_xlpm.v=0,"",_xlpm.v)) | O18: =_xlfn.LET(_xlpm.v,SUMIFS(D:D,$A:$A,$M18),IF(_xlpm.v=0,"",_xlpm.v)) | P18: =_xlfn.LET(_xlpm.v,SUMIFS(E:E,$A:$A,$M18),IF(_xlpm.v=0,"",_xlpm.v)) | Q18: =_xlfn.LET(_xlpm.v,SUMIFS(F:F,$A:$A,$M18),IF(_xlpm.v=0,"",_xlpm.v)) | R18: =_xlfn.LET(_xlpm.v,SUMIFS(G:G,$A:$A,$M18),IF(_xlpm.v=0,"",_xlpm.v)) | S18: =_xlfn.LET(_xlpm.v,SUMIFS(H:H,$A:$A,$M18),IF(_xlpm.v=0,"",_xlpm.v)) | T18: =_xlfn.LET(_xlpm.v,SUMIFS(I:I,$A:$A,$M18),IF(_xlpm.v=0,"",_xlpm.v)) | U18: =_xlfn.LET(_xlpm.v,SUMIFS(J:J,$A:$A,$M18),IF(_xlpm.v=0,"",_xlpm.v)) | V18: =_xlfn.LET(_xlpm.v,SUMIFS(K:K,$A:$A,$M18),IF(_xlpm.v=0,"",_xlpm.v)) | W18: =SUM(N18:V18) -> 0
A19: =TEXT(B19,"yyyy") & "-T" & TEXT(MONTH(B19),"00") -> 2025-T12 | B19: 46006 | C19: =COUNTIFS(INDIRECT(C$1 & "!$G$6:$G$1000"),$B19) -> 0 | D19: =COUNTIFS(INDIRECT(D$1 & "!$G$6:$G$1000"),$B19) -> 0 | E19: =COUNTIFS(INDIRECT(E$1 & "!$G$6:$G$1000"),$B19) -> 0 | F19: =COUNTIFS(INDIRECT(F$1 & "!$G$6:$G$1000"),$B19) -> 0 | G19: =COUNTIFS(INDIRECT(G$1 & "!$G$6:$G$1000"),$B19) -> 1 | H19: =COUNTIFS(INDIRECT(H$1 & "!$G$6:$G$1000"),$B19) -> 0 | I19: =COUNTIFS(INDIRECT(I$1 & "!$G$6:$G$1000"),$B19) -> 0 | J19: =COUNTIFS(INDIRECT(J$1 & "!$G$6:$G$1000"),$B19) -> 0 | K19: =COUNTIFS(INDIRECT(K$1 & "!$G$6:$G$1000"),$B19) -> 0 | N19: =_xlfn.LET(_xlpm.v,SUMIFS(C:C,$A:$A,$M19),IF(_xlpm.v=0,"",_xlpm.v)) | O19: =_xlfn.LET(_xlpm.v,SUMIFS(D:D,$A:$A,$M19),IF(_xlpm.v=0,"",_xlpm.v)) | P19: =_xlfn.LET(_xlpm.v,SUMIFS(E:E,$A:$A,$M19),IF(_xlpm.v=0,"",_xlpm.v)) | Q19: =_xlfn.LET(_xlpm.v,SUMIFS(F:F,$A:$A,$M19),IF(_xlpm.v=0,"",_xlpm.v)) | R19: =_xlfn.LET(_xlpm.v,SUMIFS(G:G,$A:$A,$M19),IF(_xlpm.v=0,"",_xlpm.v)) | S19: =_xlfn.LET(_xlpm.v,SUMIFS(H:H,$A:$A,$M19),IF(_xlpm.v=0,"",_xlpm.v)) | T19: =_xlfn.LET(_xlpm.v,SUMIFS(I:I,$A:$A,$M19),IF(_xlpm.v=0,"",_xlpm.v)) | U19: =_xlfn.LET(_xlpm.v,SUMIFS(J:J,$A:$A,$M19),IF(_xlpm.v=0,"",_xlpm.v)) | V19: =_xlfn.LET(_xlpm.v,SUMIFS(K:K,$A:$A,$M19),IF(_xlpm.v=0,"",_xlpm.v)) | W19: =SUM(N19:V19) -> 0
A20: =TEXT(B20,"yyyy") & "-T" & TEXT(MONTH(B20),"00") -> 2025-T12 | B20: 46008 | C20: =COUNTIFS(INDIRECT(C$1 & "!$G$6:$G$1000"),$B20) -> 0 | D20: =COUNTIFS(INDIRECT(D$1 & "!$G$6:$G$1000"),$B20) -> 0 | E20: =COUNTIFS(INDIRECT(E$1 & "!$G$6:$G$1000"),$B20) -> 0 | F20: =COUNTIFS(INDIRECT(F$1 & "!$G$6:$G$1000"),$B20) -> 2 | G20: =COUNTIFS(INDIRECT(G$1 & "!$G$6:$G$1000"),$B20) -> 0 | H20: =COUNTIFS(INDIRECT(H$1 & "!$G$6:$G$1000"),$B20) -> 0 | I20: =COUNTIFS(INDIRECT(I$1 & "!$G$6:$G$1000"),$B20) -> 0 | J20: =COUNTIFS(INDIRECT(J$1 & "!$G$6:$G$1000"),$B20) -> 0 | K20: =COUNTIFS(INDIRECT(K$1 & "!$G$6:$G$1000"),$B20) -> 0 | N20: =_xlfn.LET(_xlpm.v,SUMIFS(C:C,$A:$A,$M20),IF(_xlpm.v=0,"",_xlpm.v)) | O20: =_xlfn.LET(_xlpm.v,SUMIFS(D:D,$A:$A,$M20),IF(_xlpm.v=0,"",_xlpm.v)) | P20: =_xlfn.LET(_xlpm.v,SUMIFS(E:E,$A:$A,$M20),IF(_xlpm.v=0,"",_xlpm.v)) | Q20: =_xlfn.LET(_xlpm.v,SUMIFS(F:F,$A:$A,$M20),IF(_xlpm.v=0,"",_xlpm.v)) | R20: =_xlfn.LET(_xlpm.v,SUMIFS(G:G,$A:$A,$M20),IF(_xlpm.v=0,"",_xlpm.v)) | S20: =_xlfn.LET(_xlpm.v,SUMIFS(H:H,$A:$A,$M20),IF(_xlpm.v=0,"",_xlpm.v)) | T20: =_xlfn.LET(_xlpm.v,SUMIFS(I:I,$A:$A,$M20),IF(_xlpm.v=0,"",_xlpm.v)) | U20: =_xlfn.LET(_xlpm.v,SUMIFS(J:J,$A:$A,$M20),IF(_xlpm.v=0,"",_xlpm.v)) | V20: =_xlfn.LET(_xlpm.v,SUMIFS(K:K,$A:$A,$M20),IF(_xlpm.v=0,"",_xlpm.v)) | W20: =SUM(N20:V20) -> 0
A21: =TEXT(B21,"yyyy") & "-T" & TEXT(MONTH(B21),"00") -> 2025-T12 | B21: 46013 | C21: =COUNTIFS(INDIRECT(C$1 & "!$G$6:$G$1000"),$B21) -> 0 | D21: =COUNTIFS(INDIRECT(D$1 & "!$G$6:$G$1000"),$B21) -> 0 | E21: =COUNTIFS(INDIRECT(E$1 & "!$G$6:$G$1000"),$B21) -> 3 | F21: =COUNTIFS(INDIRECT(F$1 & "!$G$6:$G$1000"),$B21) -> 0 | G21: =COUNTIFS(INDIRECT(G$1 & "!$G$6:$G$1000"),$B21) -> 0 | H21: =COUNTIFS(INDIRECT(H$1 & "!$G$6:$G$1000"),$B21) -> 0 | I21: =COUNTIFS(INDIRECT(I$1 & "!$G$6:$G$1000"),$B21) -> 0 | J21: =COUNTIFS(INDIRECT(J$1 & "!$G$6:$G$1000"),$B21) -> 0 | K21: =COUNTIFS(INDIRECT(K$1 & "!$G$6:$G$1000"),$B21) -> 0 | N21: =_xlfn.LET(_xlpm.v,SUMIFS(C:C,$A:$A,$M21),IF(_xlpm.v=0,"",_xlpm.v)) | O21: =_xlfn.LET(_xlpm.v,SUMIFS(D:D,$A:$A,$M21),IF(_xlpm.v=0,"",_xlpm.v)) | P21: =_xlfn.LET(_xlpm.v,SUMIFS(E:E,$A:$A,$M21),IF(_xlpm.v=0,"",_xlpm.v)) | Q21: =_xlfn.LET(_xlpm.v,SUMIFS(F:F,$A:$A,$M21),IF(_xlpm.v=0,"",_xlpm.v)) | R21: =_xlfn.LET(_xlpm.v,SUMIFS(G:G,$A:$A,$M21),IF(_xlpm.v=0,"",_xlpm.v)) | S21: =_xlfn.LET(_xlpm.v,SUMIFS(H:H,$A:$A,$M21),IF(_xlpm.v=0,"",_xlpm.v)) | T21: =_xlfn.LET(_xlpm.v,SUMIFS(I:I,$A:$A,$M21),IF(_xlpm.v=0,"",_xlpm.v)) | U21: =_xlfn.LET(_xlpm.v,SUMIFS(J:J,$A:$A,$M21),IF(_xlpm.v=0,"",_xlpm.v)) | V21: =_xlfn.LET(_xlpm.v,SUMIFS(K:K,$A:$A,$M21),IF(_xlpm.v=0,"",_xlpm.v)) | W21: =SUM(N21:V21) -> 0
A22: =TEXT(B22,"yyyy") & "-T" & TEXT(MONTH(B22),"00") -> 2026-T01 | B22: 46028 | C22: =COUNTIFS(INDIRECT(C$1 & "!$G$6:$G$1000"),$B22) -> 0 | D22: =COUNTIFS(INDIRECT(D$1 & "!$G$6:$G$1000"),$B22) -> 0 | E22: =COUNTIFS(INDIRECT(E$1 & "!$G$6:$G$1000"),$B22) -> 0 | F22: =COUNTIFS(INDIRECT(F$1 & "!$G$6:$G$1000"),$B22) -> 1 | G22: =COUNTIFS(INDIRECT(G$1 & "!$G$6:$G$1000"),$B22) -> 0 | H22: =COUNTIFS(INDIRECT(H$1 & "!$G$6:$G$1000"),$B22) -> 0 | I22: =COUNTIFS(INDIRECT(I$1 & "!$G$6:$G$1000"),$B22) -> 0 | J22: =COUNTIFS(INDIRECT(J$1 & "!$G$6:$G$1000"),$B22) -> 0 | K22: =COUNTIFS(INDIRECT(K$1 & "!$G$6:$G$1000"),$B22) -> 0 | N22: =_xlfn.LET(_xlpm.v,SUMIFS(C:C,$A:$A,$M22),IF(_xlpm.v=0,"",_xlpm.v)) | O22: =_xlfn.LET(_xlpm.v,SUMIFS(D:D,$A:$A,$M22),IF(_xlpm.v=0,"",_xlpm.v)) | P22: =_xlfn.LET(_xlpm.v,SUMIFS(E:E,$A:$A,$M22),IF(_xlpm.v=0,"",_xlpm.v)) | Q22: =_xlfn.LET(_xlpm.v,SUMIFS(F:F,$A:$A,$M22),IF(_xlpm.v=0,"",_xlpm.v)) | R22: =_xlfn.LET(_xlpm.v,SUMIFS(G:G,$A:$A,$M22),IF(_xlpm.v=0,"",_xlpm.v)) | S22: =_xlfn.LET(_xlpm.v,SUMIFS(H:H,$A:$A,$M22),IF(_xlpm.v=0,"",_xlpm.v)) | T22: =_xlfn.LET(_xlpm.v,SUMIFS(I:I,$A:$A,$M22),IF(_xlpm.v=0,"",_xlpm.v)) | U22: =_xlfn.LET(_xlpm.v,SUMIFS(J:J,$A:$A,$M22),IF(_xlpm.v=0,"",_xlpm.v)) | V22: =_xlfn.LET(_xlpm.v,SUMIFS(K:K,$A:$A,$M22),IF(_xlpm.v=0,"",_xlpm.v))
A23: =TEXT(B23,"yyyy") & "-T" & TEXT(MONTH(B23),"00") -> 2026-T01 | B23: 46031 | C23: =COUNTIFS(INDIRECT(C$1 & "!$G$6:$G$1000"),$B23) -> 0 | D23: =COUNTIFS(INDIRECT(D$1 & "!$G$6:$G$1000"),$B23) -> 0 | E23: =COUNTIFS(INDIRECT(E$1 & "!$G$6:$G$1000"),$B23) -> 0 | F23: =COUNTIFS(INDIRECT(F$1 & "!$G$6:$G$1000"),$B23) -> 0 | G23: =COUNTIFS(INDIRECT(G$1 & "!$G$6:$G$1000"),$B23) -> 1 | H23: =COUNTIFS(INDIRECT(H$1 & "!$G$6:$G$1000"),$B23) -> 2 | I23: =COUNTIFS(INDIRECT(I$1 & "!$G$6:$G$1000"),$B23) -> 0 | J23: =COUNTIFS(INDIRECT(J$1 & "!$G$6:$G$1000"),$B23) -> 0 | K23: =COUNTIFS(INDIRECT(K$1 & "!$G$6:$G$1000"),$B23) -> 0 | N23: =_xlfn.LET(_xlpm.v,SUMIFS(C:C,$A:$A,$M23),IF(_xlpm.v=0,"",_xlpm.v)) | O23: =_xlfn.LET(_xlpm.v,SUMIFS(D:D,$A:$A,$M23),IF(_xlpm.v=0,"",_xlpm.v)) | P23: =_xlfn.LET(_xlpm.v,SUMIFS(E:E,$A:$A,$M23),IF(_xlpm.v=0,"",_xlpm.v)) | Q23: =_xlfn.LET(_xlpm.v,SUMIFS(F:F,$A:$A,$M23),IF(_xlpm.v=0,"",_xlpm.v)) | R23: =_xlfn.LET(_xlpm.v,SUMIFS(G:G,$A:$A,$M23),IF(_xlpm.v=0,"",_xlpm.v)) | S23: =_xlfn.LET(_xlpm.v,SUMIFS(H:H,$A:$A,$M23),IF(_xlpm.v=0,"",_xlpm.v)) | T23: =_xlfn.LET(_xlpm.v,SUMIFS(I:I,$A:$A,$M23),IF(_xlpm.v=0,"",_xlpm.v)) | U23: =_xlfn.LET(_xlpm.v,SUMIFS(J:J,$A:$A,$M23),IF(_xlpm.v=0,"",_xlpm.v)) | V23: =_xlfn.LET(_xlpm.v,SUMIFS(K:K,$A:$A,$M23),IF(_xlpm.v=0,"",_xlpm.v))
A24: =TEXT(B24,"yyyy") & "-T" & TEXT(MONTH(B24),"00") -> 2026-T01 | B24: 46042 | C24: =COUNTIFS(INDIRECT(C$1 & "!$G$6:$G$1000"),$B24) -> 0 | D24: =COUNTIFS(INDIRECT(D$1 & "!$G$6:$G$1000"),$B24) -> 0 | E24: =COUNTIFS(INDIRECT(E$1 & "!$G$6:$G$1000"),$B24) -> 0 | F24: =COUNTIFS(INDIRECT(F$1 & "!$G$6:$G$1000"),$B24) -> 0 | G24: =COUNTIFS(INDIRECT(G$1 & "!$G$6:$G$1000"),$B24) -> 1 | H24: =COUNTIFS(INDIRECT(H$1 & "!$G$6:$G$1000"),$B24) -> 0 | I24: =COUNTIFS(INDIRECT(I$1 & "!$G$6:$G$1000"),$B24) -> 0 | J24: =COUNTIFS(INDIRECT(J$1 & "!$G$6:$G$1000"),$B24) -> 0 | K24: =COUNTIFS(INDIRECT(K$1 & "!$G$6:$G$1000"),$B24) -> 0 | N24: =_xlfn.LET(_xlpm.v,SUMIFS(C:C,$A:$A,$M24),IF(_xlpm.v=0,"",_xlpm.v)) | O24: =_xlfn.LET(_xlpm.v,SUMIFS(D:D,$A:$A,$M24),IF(_xlpm.v=0,"",_xlpm.v)) | P24: =_xlfn.LET(_xlpm.v,SUMIFS(E:E,$A:$A,$M24),IF(_xlpm.v=0,"",_xlpm.v)) | Q24: =_xlfn.LET(_xlpm.v,SUMIFS(F:F,$A:$A,$M24),IF(_xlpm.v=0,"",_xlpm.v)) | R24: =_xlfn.LET(_xlpm.v,SUMIFS(G:G,$A:$A,$M24),IF(_xlpm.v=0,"",_xlpm.v)) | S24: =_xlfn.LET(_xlpm.v,SUMIFS(H:H,$A:$A,$M24),IF(_xlpm.v=0,"",_xlpm.v)) | T24: =_xlfn.LET(_xlpm.v,SUMIFS(I:I,$A:$A,$M24),IF(_xlpm.v=0,"",_xlpm.v)) | U24: =_xlfn.LET(_xlpm.v,SUMIFS(J:J,$A:$A,$M24),IF(_xlpm.v=0,"",_xlpm.v)) | V24: =_xlfn.LET(_xlpm.v,SUMIFS(K:K,$A:$A,$M24),IF(_xlpm.v=0,"",_xlpm.v))
A25: =TEXT(B25,"yyyy") & "-T" & TEXT(MONTH(B25),"00") -> 2026-T01 | B25: 46053 | C25: =COUNTIFS(INDIRECT(C$1 & "!$G$6:$G$1000"),$B25) -> 0 | D25: =COUNTIFS(INDIRECT(D$1 & "!$G$6:$G$1000"),$B25) -> 3 | E25: =COUNTIFS(INDIRECT(E$1 & "!$G$6:$G$1000"),$B25) -> 0 | F25: =COUNTIFS(INDIRECT(F$1 & "!$G$6:$G$1000"),$B25) -> 0 | G25: =COUNTIFS(INDIRECT(G$1 & "!$G$6:$G$1000"),$B25) -> 0 | H25: =COUNTIFS(INDIRECT(H$1 & "!$G$6:$G$1000"),$B25) -> 0 | I25: =COUNTIFS(INDIRECT(I$1 & "!$G$6:$G$1000"),$B25) -> 0 | J25: =COUNTIFS(INDIRECT(J$1 & "!$G$6:$G$1000"),$B25) -> 0 | K25: =COUNTIFS(INDIRECT(K$1 & "!$G$6:$G$1000"),$B25) -> 0 | N25: =_xlfn.LET(_xlpm.v,SUMIFS(C:C,$A:$A,$M25),IF(_xlpm.v=0,"",_xlpm.v)) | O25: =_xlfn.LET(_xlpm.v,SUMIFS(D:D,$A:$A,$M25),IF(_xlpm.v=0,"",_xlpm.v)) | P25: =_xlfn.LET(_xlpm.v,SUMIFS(E:E,$A:$A,$M25),IF(_xlpm.v=0,"",_xlpm.v)) | Q25: =_xlfn.LET(_xlpm.v,SUMIFS(F:F,$A:$A,$M25),IF(_xlpm.v=0,"",_xlpm.v)) | R25: =_xlfn.LET(_xlpm.v,SUMIFS(G:G,$A:$A,$M25),IF(_xlpm.v=0,"",_xlpm.v)) | S25: =_xlfn.LET(_xlpm.v,SUMIFS(H:H,$A:$A,$M25),IF(_xlpm.v=0,"",_xlpm.v)) | T25: =_xlfn.LET(_xlpm.v,SUMIFS(I:I,$A:$A,$M25),IF(_xlpm.v=0,"",_xlpm.v)) | U25: =_xlfn.LET(_xlpm.v,SUMIFS(J:J,$A:$A,$M25),IF(_xlpm.v=0,"",_xlpm.v)) | V25: =_xlfn.LET(_xlpm.v,SUMIFS(K:K,$A:$A,$M25),IF(_xlpm.v=0,"",_xlpm.v))
A26: =TEXT(B26,"yyyy") & "-T" & TEXT(MONTH(B26),"00") -> 2026-T02 | B26: 46055 | C26: =COUNTIFS(INDIRECT(C$1 & "!$G$6:$G$1000"),$B26) -> 3 | D26: =COUNTIFS(INDIRECT(D$1 & "!$G$6:$G$1000"),$B26) -> 0 | E26: =COUNTIFS(INDIRECT(E$1 & "!$G$6:$G$1000"),$B26) -> 0 | F26: =COUNTIFS(INDIRECT(F$1 & "!$G$6:$G$1000"),$B26) -> 0 | G26: =COUNTIFS(INDIRECT(G$1 & "!$G$6:$G$1000"),$B26) -> 0 | H26: =COUNTIFS(INDIRECT(H$1 & "!$G$6:$G$1000"),$B26) -> 0 | I26: =COUNTIFS(INDIRECT(I$1 & "!$G$6:$G$1000"),$B26) -> 0 | J26: =COUNTIFS(INDIRECT(J$1 & "!$G$6:$G$1000"),$B26) -> 0 | K26: =COUNTIFS(INDIRECT(K$1 & "!$G$6:$G$1000"),$B26) -> 0 | N26: =_xlfn.LET(_xlpm.v,SUMIFS(C:C,$A:$A,$M26),IF(_xlpm.v=0,"",_xlpm.v)) | O26: =_xlfn.LET(_xlpm.v,SUMIFS(D:D,$A:$A,$M26),IF(_xlpm.v=0,"",_xlpm.v)) | P26: =_xlfn.LET(_xlpm.v,SUMIFS(E:E,$A:$A,$M26),IF(_xlpm.v=0,"",_xlpm.v)) | Q26: =_xlfn.LET(_xlpm.v,SUMIFS(F:F,$A:$A,$M26),IF(_xlpm.v=0,"",_xlpm.v)) | R26: =_xlfn.LET(_xlpm.v,SUMIFS(G:G,$A:$A,$M26),IF(_xlpm.v=0,"",_xlpm.v)) | S26: =_xlfn.LET(_xlpm.v,SUMIFS(H:H,$A:$A,$M26),IF(_xlpm.v=0,"",_xlpm.v)) | T26: =_xlfn.LET(_xlpm.v,SUMIFS(I:I,$A:$A,$M26),IF(_xlpm.v=0,"",_xlpm.v)) | U26: =_xlfn.LET(_xlpm.v,SUMIFS(J:J,$A:$A,$M26),IF(_xlpm.v=0,"",_xlpm.v)) | V26: =_xlfn.LET(_xlpm.v,SUMIFS(K:K,$A:$A,$M26),IF(_xlpm.v=0,"",_xlpm.v))
A27: =TEXT(B27,"yyyy") & "-T" & TEXT(MONTH(B27),"00") -> 2026-T02 | B27: 46058 | C27: =COUNTIFS(INDIRECT(C$1 & "!$G$6:$G$1000"),$B27) -> 0 | D27: =COUNTIFS(INDIRECT(D$1 & "!$G$6:$G$1000"),$B27) -> 2 | E27: =COUNTIFS(INDIRECT(E$1 & "!$G$6:$G$1000"),$B27) -> 0 | F27: =COUNTIFS(INDIRECT(F$1 & "!$G$6:$G$1000"),$B27) -> 0 | G27: =COUNTIFS(INDIRECT(G$1 & "!$G$6:$G$1000"),$B27) -> 0 | H27: =COUNTIFS(INDIRECT(H$1 & "!$G$6:$G$1000"),$B27) -> 1 | I27: =COUNTIFS(INDIRECT(I$1 & "!$G$6:$G$1000"),$B27) -> 0 | J27: =COUNTIFS(INDIRECT(J$1 & "!$G$6:$G$1000"),$B27) -> 0 | K27: =COUNTIFS(INDIRECT(K$1 & "!$G$6:$G$1000"),$B27) -> 0 | N27: =_xlfn.LET(_xlpm.v,SUMIFS(C:C,$A:$A,$M27),IF(_xlpm.v=0,"",_xlpm.v)) | O27: =_xlfn.LET(_xlpm.v,SUMIFS(D:D,$A:$A,$M27),IF(_xlpm.v=0,"",_xlpm.v)) | P27: =_xlfn.LET(_xlpm.v,SUMIFS(E:E,$A:$A,$M27),IF(_xlpm.v=0,"",_xlpm.v)) | Q27: =_xlfn.LET(_xlpm.v,SUMIFS(F:F,$A:$A,$M27),IF(_xlpm.v=0,"",_xlpm.v)) | R27: =_xlfn.LET(_xlpm.v,SUMIFS(G:G,$A:$A,$M27),IF(_xlpm.v=0,"",_xlpm.v)) | S27: =_xlfn.LET(_xlpm.v,SUMIFS(H:H,$A:$A,$M27),IF(_xlpm.v=0,"",_xlpm.v)) | T27: =_xlfn.LET(_xlpm.v,SUMIFS(I:I,$A:$A,$M27),IF(_xlpm.v=0,"",_xlpm.v)) | U27: =_xlfn.LET(_xlpm.v,SUMIFS(J:J,$A:$A,$M27),IF(_xlpm.v=0,"",_xlpm.v)) | V27: =_xlfn.LET(_xlpm.v,SUMIFS(K:K,$A:$A,$M27),IF(_xlpm.v=0,"",_xlpm.v))
A28: =TEXT(B28,"yyyy") & "-T" & TEXT(MONTH(B28),"00") -> 2026-T02 | B28: 46061 | C28: =COUNTIFS(INDIRECT(C$1 & "!$G$6:$G$1000"),$B28) -> 0 | D28: =COUNTIFS(INDIRECT(D$1 & "!$G$6:$G$1000"),$B28) -> 0 | E28: =COUNTIFS(INDIRECT(E$1 & "!$G$6:$G$1000"),$B28) -> 0 | F28: =COUNTIFS(INDIRECT(F$1 & "!$G$6:$G$1000"),$B28) -> 0 | G28: =COUNTIFS(INDIRECT(G$1 & "!$G$6:$G$1000"),$B28) -> 2 | H28: =COUNTIFS(INDIRECT(H$1 & "!$G$6:$G$1000"),$B28) -> 0 | I28: =COUNTIFS(INDIRECT(I$1 & "!$G$6:$G$1000"),$B28) -> 0 | J28: =COUNTIFS(INDIRECT(J$1 & "!$G$6:$G$1000"),$B28) -> 0 | K28: =COUNTIFS(INDIRECT(K$1 & "!$G$6:$G$1000"),$B28) -> 0 | N28: =_xlfn.LET(_xlpm.v,SUMIFS(C:C,$A:$A,$M28),IF(_xlpm.v=0,"",_xlpm.v)) | O28: =_xlfn.LET(_xlpm.v,SUMIFS(D:D,$A:$A,$M28),IF(_xlpm.v=0,"",_xlpm.v)) | P28: =_xlfn.LET(_xlpm.v,SUMIFS(E:E,$A:$A,$M28),IF(_xlpm.v=0,"",_xlpm.v)) | Q28: =_xlfn.LET(_xlpm.v,SUMIFS(F:F,$A:$A,$M28),IF(_xlpm.v=0,"",_xlpm.v)) | R28: =_xlfn.LET(_xlpm.v,SUMIFS(G:G,$A:$A,$M28),IF(_xlpm.v=0,"",_xlpm.v)) | S28: =_xlfn.LET(_xlpm.v,SUMIFS(H:H,$A:$A,$M28),IF(_xlpm.v=0,"",_xlpm.v)) | T28: =_xlfn.LET(_xlpm.v,SUMIFS(I:I,$A:$A,$M28),IF(_xlpm.v=0,"",_xlpm.v)) | U28: =_xlfn.LET(_xlpm.v,SUMIFS(J:J,$A:$A,$M28),IF(_xlpm.v=0,"",_xlpm.v)) | V28: =_xlfn.LET(_xlpm.v,SUMIFS(K:K,$A:$A,$M28),IF(_xlpm.v=0,"",_xlpm.v))
A29: =TEXT(B29,"yyyy") & "-T" & TEXT(MONTH(B29),"00") -> 2026-T03 | B29: 46089 | C29: =COUNTIFS(INDIRECT(C$1 & "!$G$6:$G$1000"),$B29) -> 0 | D29: =COUNTIFS(INDIRECT(D$1 & "!$G$6:$G$1000"),$B29) -> 1 | E29: =COUNTIFS(INDIRECT(E$1 & "!$G$6:$G$1000"),$B29) -> 0 | F29: =COUNTIFS(INDIRECT(F$1 & "!$G$6:$G$1000"),$B29) -> 0 | G29: =COUNTIFS(INDIRECT(G$1 & "!$G$6:$G$1000"),$B29) -> 0 | H29: =COUNTIFS(INDIRECT(H$1 & "!$G$6:$G$1000"),$B29) -> 0 | I29: =COUNTIFS(INDIRECT(I$1 & "!$G$6:$G$1000"),$B29) -> 0 | J29: =COUNTIFS(INDIRECT(J$1 & "!$G$6:$G$1000"),$B29) -> 0 | K29: =COUNTIFS(INDIRECT(K$1 & "!$G$6:$G$1000"),$B29) -> 0 | N29: =_xlfn.LET(_xlpm.v,SUMIFS(C:C,$A:$A,$M29),IF(_xlpm.v=0,"",_xlpm.v)) | O29: =_xlfn.LET(_xlpm.v,SUMIFS(D:D,$A:$A,$M29),IF(_xlpm.v=0,"",_xlpm.v)) | P29: =_xlfn.LET(_xlpm.v,SUMIFS(E:E,$A:$A,$M29),IF(_xlpm.v=0,"",_xlpm.v)) | Q29: =_xlfn.LET(_xlpm.v,SUMIFS(F:F,$A:$A,$M29),IF(_xlpm.v=0,"",_xlpm.v)) | R29: =_xlfn.LET(_xlpm.v,SUMIFS(G:G,$A:$A,$M29),IF(_xlpm.v=0,"",_xlpm.v)) | S29: =_xlfn.LET(_xlpm.v,SUMIFS(H:H,$A:$A,$M29),IF(_xlpm.v=0,"",_xlpm.v)) | T29: =_xlfn.LET(_xlpm.v,SUMIFS(I:I,$A:$A,$M29),IF(_xlpm.v=0,"",_xlpm.v)) | U29: =_xlfn.LET(_xlpm.v,SUMIFS(J:J,$A:$A,$M29),IF(_xlpm.v=0,"",_xlpm.v)) | V29: =_xlfn.LET(_xlpm.v,SUMIFS(K:K,$A:$A,$M29),IF(_xlpm.v=0,"",_xlpm.v))
A30: =TEXT(B30,"yyyy") & "-T" & TEXT(MONTH(B30),"00") -> 2026-T03 | B30: 46090 | C30: =COUNTIFS(INDIRECT(C$1 & "!$G$6:$G$1000"),$B30) -> 0 | D30: =COUNTIFS(INDIRECT(D$1 & "!$G$6:$G$1000"),$B30) -> 1 | E30: =COUNTIFS(INDIRECT(E$1 & "!$G$6:$G$1000"),$B30) -> 0 | F30: =COUNTIFS(INDIRECT(F$1 & "!$G$6:$G$1000"),$B30) -> 0 | G30: =COUNTIFS(INDIRECT(G$1 & "!$G$6:$G$1000"),$B30) -> 0 | H30: =COUNTIFS(INDIRECT(H$1 & "!$G$6:$G$1000"),$B30) -> 0 | I30: =COUNTIFS(INDIRECT(I$1 & "!$G$6:$G$1000"),$B30) -> 0 | J30: =COUNTIFS(INDIRECT(J$1 & "!$G$6:$G$1000"),$B30) -> 0 | K30: =COUNTIFS(INDIRECT(K$1 & "!$G$6:$G$1000"),$B30) -> 0 | N30: =_xlfn.LET(_xlpm.v,SUMIFS(C:C,$A:$A,$M30),IF(_xlpm.v=0,"",_xlpm.v)) | O30: =_xlfn.LET(_xlpm.v,SUMIFS(D:D,$A:$A,$M30),IF(_xlpm.v=0,"",_xlpm.v)) | P30: =_xlfn.LET(_xlpm.v,SUMIFS(E:E,$A:$A,$M30),IF(_xlpm.v=0,"",_xlpm.v)) | Q30: =_xlfn.LET(_xlpm.v,SUMIFS(F:F,$A:$A,$M30),IF(_xlpm.v=0,"",_xlpm.v)) | R30: =_xlfn.LET(_xlpm.v,SUMIFS(G:G,$A:$A,$M30),IF(_xlpm.v=0,"",_xlpm.v)) | S30: =_xlfn.LET(_xlpm.v,SUMIFS(H:H,$A:$A,$M30),IF(_xlpm.v=0,"",_xlpm.v)) | T30: =_xlfn.LET(_xlpm.v,SUMIFS(I:I,$A:$A,$M30),IF(_xlpm.v=0,"",_xlpm.v)) | U30: =_xlfn.LET(_xlpm.v,SUMIFS(J:J,$A:$A,$M30),IF(_xlpm.v=0,"",_xlpm.v)) | V30: =_xlfn.LET(_xlpm.v,SUMIFS(K:K,$A:$A,$M30),IF(_xlpm.v=0,"",_xlpm.v))
A31: =TEXT(B31,"yyyy") & "-T" & TEXT(MONTH(B31),"00") -> 2026-T03 | B31: 46091 | C31: =COUNTIFS(INDIRECT(C$1 & "!$G$6:$G$1000"),$B31) -> 2 | D31: =COUNTIFS(INDIRECT(D$1 & "!$G$6:$G$1000"),$B31) -> 0 | E31: =COUNTIFS(INDIRECT(E$1 & "!$G$6:$G$1000"),$B31) -> 0 | F31: =COUNTIFS(INDIRECT(F$1 & "!$G$6:$G$1000"),$B31) -> 0 | G31: =COUNTIFS(INDIRECT(G$1 & "!$G$6:$G$1000"),$B31) -> 0 | H31: =COUNTIFS(INDIRECT(H$1 & "!$G$6:$G$1000"),$B31) -> 0 | I31: =COUNTIFS(INDIRECT(I$1 & "!$G$6:$G$1000"),$B31) -> 0 | J31: =COUNTIFS(INDIRECT(J$1 & "!$G$6:$G$1000"),$B31) -> 0 | K31: =COUNTIFS(INDIRECT(K$1 & "!$G$6:$G$1000"),$B31) -> 0
A32: =TEXT(B32,"yyyy") & "-T" & TEXT(MONTH(B32),"00") -> 2026-T03 | B32: 46092 | C32: =COUNTIFS(INDIRECT(C$1 & "!$G$6:$G$1000"),$B32) -> 0 | D32: =COUNTIFS(INDIRECT(D$1 & "!$G$6:$G$1000"),$B32) -> 2 | E32: =COUNTIFS(INDIRECT(E$1 & "!$G$6:$G$1000"),$B32) -> 0 | F32: =COUNTIFS(INDIRECT(F$1 & "!$G$6:$G$1000"),$B32) -> 0 | G32: =COUNTIFS(INDIRECT(G$1 & "!$G$6:$G$1000"),$B32) -> 0 | H32: =COUNTIFS(INDIRECT(H$1 & "!$G$6:$G$1000"),$B32) -> 0 | I32: =COUNTIFS(INDIRECT(I$1 & "!$G$6:$G$1000"),$B32) -> 0 | J32: =COUNTIFS(INDIRECT(J$1 & "!$G$6:$G$1000"),$B32) -> 0 | K32: =COUNTIFS(INDIRECT(K$1 & "!$G$6:$G$1000"),$B32) -> 0
A33: =TEXT(B33,"yyyy") & "-T" & TEXT(MONTH(B33),"00") -> 2026-T03 | B33: 46096 | C33: =COUNTIFS(INDIRECT(C$1 & "!$G$6:$G$1000"),$B33) -> 0 | D33: =COUNTIFS(INDIRECT(D$1 & "!$G$6:$G$1000"),$B33) -> 0 | E33: =COUNTIFS(INDIRECT(E$1 & "!$G$6:$G$1000"),$B33) -> 0 | F33: =COUNTIFS(INDIRECT(F$1 & "!$G$6:$G$1000"),$B33) -> 0 | G33: =COUNTIFS(INDIRECT(G$1 & "!$G$6:$G$1000"),$B33) -> 0 | H33: =COUNTIFS(INDIRECT(H$1 & "!$G$6:$G$1000"),$B33) -> 4 | I33: =COUNTIFS(INDIRECT(I$1 & "!$G$6:$G$1000"),$B33) -> 0 | J33: =COUNTIFS(INDIRECT(J$1 & "!$G$6:$G$1000"),$B33) -> 0 | K33: =COUNTIFS(INDIRECT(K$1 & "!$G$6:$G$1000"),$B33) -> 0
A34: =TEXT(B34,"yyyy") & "-T" & TEXT(MONTH(B34),"00") -> 2026-T03 | B34: 46098 | C34: =COUNTIFS(INDIRECT(C$1 & "!$G$6:$G$1000"),$B34) -> 0 | D34: =COUNTIFS(INDIRECT(D$1 & "!$G$6:$G$1000"),$B34) -> 0 | E34: =COUNTIFS(INDIRECT(E$1 & "!$G$6:$G$1000"),$B34) -> 1 | F34: =COUNTIFS(INDIRECT(F$1 & "!$G$6:$G$1000"),$B34) -> 0 | G34: =COUNTIFS(INDIRECT(G$1 & "!$G$6:$G$1000"),$B34) -> 0 | H34: =COUNTIFS(INDIRECT(H$1 & "!$G$6:$G$1000"),$B34) -> 0 | I34: =COUNTIFS(INDIRECT(I$1 & "!$G$6:$G$1000"),$B34) -> 0 | J34: =COUNTIFS(INDIRECT(J$1 & "!$G$6:$G$1000"),$B34) -> 0 | K34: =COUNTIFS(INDIRECT(K$1 & "!$G$6:$G$1000"),$B34) -> 1
A35: =TEXT(B35,"yyyy") & "-T" & TEXT(MONTH(B35),"00") -> 2026-T03 | B35: 46099 | C35: =COUNTIFS(INDIRECT(C$1 & "!$G$6:$G$1000"),$B35) -> 0 | D35: =COUNTIFS(INDIRECT(D$1 & "!$G$6:$G$1000"),$B35) -> 0 | E35: =COUNTIFS(INDIRECT(E$1 & "!$G$6:$G$1000"),$B35) -> 0 | F35: =COUNTIFS(INDIRECT(F$1 & "!$G$6:$G$1000"),$B35) -> 0 | G35: =COUNTIFS(INDIRECT(G$1 & "!$G$6:$G$1000"),$B35) -> 1 | H35: =COUNTIFS(INDIRECT(H$1 & "!$G$6:$G$1000"),$B35) -> 0 | I35: =COUNTIFS(INDIRECT(I$1 & "!$G$6:$G$1000"),$B35) -> 0 | J35: =COUNTIFS(INDIRECT(J$1 & "!$G$6:$G$1000"),$B35) -> 0 | K35: =COUNTIFS(INDIRECT(K$1 & "!$G$6:$G$1000"),$B35) -> 0
A36: =TEXT(B36,"yyyy") & "-T" & TEXT(MONTH(B36),"00") -> 2026-T03 | B36: 46100 | C36: =COUNTIFS(INDIRECT(C$1 & "!$G$6:$G$1000"),$B36) -> 0 | D36: =COUNTIFS(INDIRECT(D$1 & "!$G$6:$G$1000"),$B36) -> 1 | E36: =COUNTIFS(INDIRECT(E$1 & "!$G$6:$G$1000"),$B36) -> 0 | F36: =COUNTIFS(INDIRECT(F$1 & "!$G$6:$G$1000"),$B36) -> 0 | G36: =COUNTIFS(INDIRECT(G$1 & "!$G$6:$G$1000"),$B36) -> 0 | H36: =COUNTIFS(INDIRECT(H$1 & "!$G$6:$G$1000"),$B36) -> 0 | I36: =COUNTIFS(INDIRECT(I$1 & "!$G$6:$G$1000"),$B36) -> 0 | J36: =COUNTIFS(INDIRECT(J$1 & "!$G$6:$G$1000"),$B36) -> 0 | K36: =COUNTIFS(INDIRECT(K$1 & "!$G$6:$G$1000"),$B36) -> 0
A37: =TEXT(B37,"yyyy") & "-T" & TEXT(MONTH(B37),"00") -> 2026-T03 | B37: 46101 | C37: =COUNTIFS(INDIRECT(C$1 & "!$G$6:$G$1000"),$B37) -> 0 | D37: =COUNTIFS(INDIRECT(D$1 & "!$G$6:$G$1000"),$B37) -> 0 | E37: =COUNTIFS(INDIRECT(E$1 & "!$G$6:$G$1000"),$B37) -> 0 | F37: =COUNTIFS(INDIRECT(F$1 & "!$G$6:$G$1000"),$B37) -> 0 | G37: =COUNTIFS(INDIRECT(G$1 & "!$G$6:$G$1000"),$B37) -> 5 | H37: =COUNTIFS(INDIRECT(H$1 & "!$G$6:$G$1000"),$B37) -> 0 | I37: =COUNTIFS(INDIRECT(I$1 & "!$G$6:$G$1000"),$B37) -> 0 | J37: =COUNTIFS(INDIRECT(J$1 & "!$G$6:$G$1000"),$B37) -> 0 | K37: =COUNTIFS(INDIRECT(K$1 & "!$G$6:$G$1000"),$B37) -> 0
A38: =TEXT(B38,"yyyy") & "-T" & TEXT(MONTH(B38),"00") -> 2026-T03 | B38: 46105 | C38: =COUNTIFS(INDIRECT(C$1 & "!$G$6:$G$1000"),$B38) -> 0 | D38: =COUNTIFS(INDIRECT(D$1 & "!$G$6:$G$1000"),$B38) -> 2 | E38: =COUNTIFS(INDIRECT(E$1 & "!$G$6:$G$1000"),$B38) -> 0 | F38: =COUNTIFS(INDIRECT(F$1 & "!$G$6:$G$1000"),$B38) -> 0 | G38: =COUNTIFS(INDIRECT(G$1 & "!$G$6:$G$1000"),$B38) -> 0 | H38: =COUNTIFS(INDIRECT(H$1 & "!$G$6:$G$1000"),$B38) -> 0 | I38: =COUNTIFS(INDIRECT(I$1 & "!$G$6:$G$1000"),$B38) -> 0 | J38: =COUNTIFS(INDIRECT(J$1 & "!$G$6:$G$1000"),$B38) -> 0 | K38: =COUNTIFS(INDIRECT(K$1 & "!$G$6:$G$1000"),$B38) -> 0
A39: =TEXT(B39,"yyyy") & "-T" & TEXT(MONTH(B39),"00") -> 2026-T03 | B39: 46106 | C39: =COUNTIFS(INDIRECT(C$1 & "!$G$6:$G$1000"),$B39) -> 0 | D39: =COUNTIFS(INDIRECT(D$1 & "!$G$6:$G$1000"),$B39) -> 0 | E39: =COUNTIFS(INDIRECT(E$1 & "!$G$6:$G$1000"),$B39) -> 0 | F39: =COUNTIFS(INDIRECT(F$1 & "!$G$6:$G$1000"),$B39) -> 0 | G39: =COUNTIFS(INDIRECT(G$1 & "!$G$6:$G$1000"),$B39) -> 1 | H39: =COUNTIFS(INDIRECT(H$1 & "!$G$6:$G$1000"),$B39) -> 0 | I39: =COUNTIFS(INDIRECT(I$1 & "!$G$6:$G$1000"),$B39) -> 0 | J39: =COUNTIFS(INDIRECT(J$1 & "!$G$6:$G$1000"),$B39) -> 0 | K39: =COUNTIFS(INDIRECT(K$1 & "!$G$6:$G$1000"),$B39) -> 0
A40: =TEXT(B40,"yyyy") & "-T" & TEXT(MONTH(B40),"00") -> 2026-T03 | B40: 46108 | C40: =COUNTIFS(INDIRECT(C$1 & "!$G$6:$G$1000"),$B40) -> 0 | D40: =COUNTIFS(INDIRECT(D$1 & "!$G$6:$G$1000"),$B40) -> 0 | E40: =COUNTIFS(INDIRECT(E$1 & "!$G$6:$G$1000"),$B40) -> 2 | F40: =COUNTIFS(INDIRECT(F$1 & "!$G$6:$G$1000"),$B40) -> 0 | G40: =COUNTIFS(INDIRECT(G$1 & "!$G$6:$G$1000"),$B40) -> 0 | H40: =COUNTIFS(INDIRECT(H$1 & "!$G$6:$G$1000"),$B40) -> 0 | I40: =COUNTIFS(INDIRECT(I$1 & "!$G$6:$G$1000"),$B40) -> 0 | J40: =COUNTIFS(INDIRECT(J$1 & "!$G$6:$G$1000"),$B40) -> 0 | K40: =COUNTIFS(INDIRECT(K$1 & "!$G$6:$G$1000"),$B40) -> 0
...

Sheet Cert_Matrix
A1: CERTIFICATION MATRIX | N1: [X] = Bắt buộc phải được cấp chứng nhận vận hành
A2: Date update: 05/02/2026 | N2: [Ô trống] = Không yêu cầu chứng nhận an toàn
A4: BỘ PHẬN | B4: CUTTING | L4: GOLF ROLLING | X4: GOLF FINISHING | AH4: GOLF BUFFING | AR4: GOLF DIPPING | AZ4: GOLF GRAPHICS | BI4: ARROW BLANK | BZ4: ARROW GRAPHICS | CE4: KAYAK | CV4: QC | DT4: CHUNG
